Workbook
Name accumulative_tax: '1Healthcare'!$AD$2:$AD$1001
Name accumulative_tax_protection: '1Healthcare'!$BE$2:$BE$1001
Name avg_infection_rate_protection: '1Healthcare'!$BJ$3
Name avg_tax_no_protection: '1Healthcare'!$BR$1
Name avg_tax_protection: '1Healthcare'!$BR$2
Name disease_die: '1Healthcare'!$AA$2:$AA$1001
Name disease_die_protection: '1Healthcare'!$BB$2:$BB$1001
Name disease_dieout: '1Healthcare'!$W$1
Name I1_: '1Healthcare'!$L$2
Name infection_rate: '1Healthcare'!$W$3
Name It: '1Healthcare'!$R$2:$R$101
Name It_protection: '1Healthcare'!$AS$2:$AS$101
Name N: '1Healthcare'!$L$11
Name p_die: '1Healthcare'!$L$8
Name p_disease_dieout_protection: '1Healthcare'!$BJ$2
Name p_encounter: '1Healthcare'!$L$4
Name p_encounter_protection: '1Healthcare'!$L$5
Name p_infected: '1Healthcare'!$L$6
Name p_population_dieout_protection: '1Healthcare'!$BJ$1
Name p1_: '1Healthcare'!$L$9
Name polulation_die: '1Healthcare'!$AB$2:$AB$1001
Name polulation_die_protection: '1Healthcare'!$BC$2:$BC$1001
Name population: '1Healthcare'!$L$3
Name population_dieout: '1Healthcare'!$W$2
Name r_infection: '1Healthcare'!$AC$2:$AC$1001
Name r_infection_protection: '1Healthcare'!$BD$2:$BD$1001
Name Dt: '1Healthcare'!$S$2:$S$101
Name Dt_protection: '1Healthcare'!$AT$2:$AT$101
Name S1_: '1Healthcare'!$L$1
Name St: '1Healthcare'!$Q$2:$Q$101
Name St_protection: '1Healthcare'!$AR$2:$AR$101
Name p_infected_protection: '1Healthcare'!$L$7
Name p1_protection: '1Healthcare'!$L$10

Sheet 00_Project_Overview
A1: Healthcare Infectious Disease Simulation
A3: Stochastic dynamic modeling • Monte Carlo simulation • intervention scenario analysis • uncertainty quantification
A5: Problem
A6: A remote village begins with 100 residents: 95 susceptible and 5 infected. In every period, each infected person has a 10% probability of dying. An infected person encounters a particular susceptible with probability 5%; conditional on an encounter, the susceptible becomes infected with probability 50%. The project models the village for 100 periods and evaluates outcomes across 1,000 simulated villages. A protection intervention reduces the conditional infection probability during an encounter from 50% to 10%, while leaving the encounter probability unchanged. The analysis asks whether protection changes population survival, disease extinction, cumulative infection, and the economic value of preserving the tax-paying population.
A12: Model
A13: State / parameter | B13: Definition | D13: No protection: q_t = (1 − 0.05×0.50)^{I_t} = 0.975^{I_t} S_{t+1} ~ Binomial(S_t, q_t)
A14: S_t | B14: Number of susceptible residents in period t
A15: I_t | B15: Number of infected residents in period t
A16: D_t | B16: Cumulative deaths through period t | D16: Protection: q_t^P = (1 − 0.05×0.10)^{I_t} = 0.995^{I_t} S_{t+1}^P ~ Binomial(S_t^P, q_t^P)
A17: Initial state | B17: S₁ = 95, I₁ = 5, D₁ = 0
A18: No-protection transmission | B18: Per infected–susceptible pair: 0.05 × 0.50 = 0.025
A19: Protection transmission | B19: Per infected–susceptible pair: 0.05 × 0.10 = 0.005 | D19: Infected population update: I_{t+1} = surviving infected + newly infected Surviving infected ~ Binomial(I_t, 0.90); newly infected = S_t − S_{t+1}.
A20: State identity | B20: S_t + I_t + D_t = 100
A23: Simulation Design
A24: 1. Simulate one 100-period sample path for the village under no protection and under protection. 2. At each transition, draw the number remaining susceptible and the number of infected survivors from binomial distributions using RAND() and BINOM.INV(). 3. Record end-of-horizon indicators for population die-out (D₁₀₀ = 100) and disease die-out (I₁₀₀ = 0), the cumulative infection rate, and cumulative tax revenue. 4. Replicate the sample path across N = 1,000 villages using Excel Data Tables. 5. Estimate probabilities/means and 95% confidence intervals from the Monte Carlo sample. 6. Compare the two scenarios and examine whether estimates stabilize as the simulation sample increases.
A31: Analytical Questions
A32: Question | B32: Metric | C32: Comparison / decision use
A33: Population survival | B33: P(D₁₀₀ = 100) | C33: How strongly does protection reduce catastrophic population loss?
A34: Disease extinction | B34: P(I₁₀₀ = 0) | C34: Does protection materially change whether infection is extinct by period 100?
A35: Cumulative infection | B35: (I₁₀₀ + D₁₀₀) / 100 | C35: How much of the original population has ever been infected?
A36: Economic preservation | B36: Cumulative tax revenue ($000s) | C36: How much additional tax base is preserved under protection?
A39: Interpretation & Managerial / Analytical Implications
A40: The intervention is evaluated as a risk-reduction policy rather than only as a disease-extinction policy. In this stylized system, lowering transmission can preserve substantially more of the population and therefore a larger cumulative tax base, even when the disease is ultimately extinct in most simulated villages under both scenarios. The comparison illustrates an important simulation insight: a policy can create economic and survival value by changing the path of a dynamic process, not merely its terminal disease status. Confidence intervals quantify Monte Carlo uncertainty, while the convergence analysis checks whether the estimated scenario differences are stable as the number of simulated villages grows.
A49: Limitations
A50: This is a stylized stochastic model, not an epidemiological forecast. It assumes homogeneous encounter risk, fixed transmission and mortality probabilities, no recovery state, no births or migration, universal protection in the intervention scenario, and no behavioral adaptation. The economic calculation values preserved population through gross cumulative tax revenue and does not subtract the cost of protection or other health/economic costs. Results are conditional on the specified 100-period horizon and parameter assumptions; Monte Carlo estimates also retain finite-sample simulation error.

Sheet 1Healthcare
A1: How to Read the Calculation Sheet | J1: INPUT | K1: S1 | L1: 95 | N1: Sample Path | O1: t | P1: pt | Q1: St | R1: It | S1: Dt | U1: STAT | V1: disease_dieout | W1: =IF($R$101=0,1,0) -> 1 | Y1: Data Table | Z1: vilages | AA1: disease_die | AB1: polulation_die | AC1: r(infection) | AD1: accumulative_tax ($000s) | AF1: OUTPUT | AG1: Qa | AH1: p(population_dieout) | AI1: =AVERAGE(polulation_die) -> 0.993 | AJ1: 95%CI_LB | AK1: =AI1-1.96*STDEV(polulation_die)/SQRT(N) -> 0.98782992 | AL1: 95%CI_HB | AM1: =AI1+1.96*STDEV(polulation_die)/SQRT(N) -> 0.99817008 | AO1: Sample Path | AP1: t | AQ1: pt | AR1: St_protection | AS1: It_protection | AT1: Dt_protection | AV1: STAT | AW1: disease_dieout | AX1: =IF($AS$101=0,1,0) -> 1 | AZ1: Data Table | BA1: vilages | BB1: disease_die_protection | BC1: polulation_die_protection | BD1: r(infection_protection) | BE1: accumulative_tax_protection ($000s) | BG1: OUTPUT | BH1: Qd | BI1: p(population_dieout_protection) | BJ1: =AVERAGE(polulation_die_protection) -> 0.56 | BK1: 95%CI_LB | BL1: =BJ1-1.96*STDEV(polulation_die_protection)/SQRT(N) -> 0.52921822 | BM1: 95%CI_HB | BN1: =p_population_dieout_protection+1.96*STDEV(polulation_die_protection)/SQRT(N) -> 0.59078178 | BP1: Qe | BQ1: avg_tax_no_protection ($000s) | BR1: =AVERAGE(accumulative_tax) -> 12608.37 | BS1: 95%CI_LB | BT1: =avg_tax_no_protection-1.96*STDEV(accumulative_tax)/SQRT(N) -> 12548.105 | BU1: 95%CI_HB | BV1: =avg_tax_no_protection+1.96*STDEV(accumulative_tax)/SQRT(N) -> 12668.635
K2: I1 | L2: 5 | O2: {=_xlfn.SEQUENCE(100)} -> 1 | P2: =(1-p_encounter*p_infected)^I1_ -> 0.88109569 | Q2: =S1_ -> 95 | R2: =I1_ -> 5 | S2: =population-S1_-I1_ -> 0 | V2: population_dieout | W2: =IF($S$101=100,1,0) -> 1 | Z2: {=_xlfn.SEQUENCE(1000)} -> 1 | AA2: =disease_dieout -> 1 | AB2: =population_dieout -> 1 | AC2: =infection_rate -> 1 | AD2: =W4 -> 11320 | AG2: Qb | AH2: p(disease_dieout) | AI2: =AVERAGE(disease_die) -> 0.993 | AJ2: 95%CI_LB | AK2: =AI2-1.96*STDEV(disease_die)/SQRT(N) -> 0.98782992 | AL2: 95%CI_HB | AM2: =AI2+1.96*STDEV(disease_die)/SQRT(N) -> 0.99817008 | AP2: {=_xlfn.SEQUENCE(100)} -> 1 | AQ2: =(1-p_encounter_protection*p_infected_protection)^I1_ -> 0.97524875 | AR2: =S1_ -> 95 | AS2: =I1_ -> 5 | AT2: =population-AR2-AS2 -> 0 | AW2: population_dieout | AX2: =IF($AT$101=100,1,0) -> 1 | BA2: {=_xlfn.SEQUENCE(1000)} -> 1 | BB2: =AX1 -> 1 | BC2: =AX2 -> 1 | BD2: =AX3 -> 1 | BE2: =AX4 -> 17590 | BI2: p(disease_dieout_protection) | BJ2: =AVERAGE(disease_die_protection) -> 0.996 | BK2: 95%CI_LB | BL2: =BJ2-1.96*STDEV(disease_die_protection)/SQRT(N) -> 0.99208589 | BM2: 95%CI_HB | BN2: =p_disease_dieout_protection+1.96*STDEV(disease_die_protection)/SQRT(N) -> 0.99991411 | BQ2: avg_tax_protection ($000s) | BR2: =AVERAGE(accumulative_tax_protection) -> 17138.71 | BS2: 95%CI_LB | BT2: =avg_tax_protection-1.96*STDEV(accumulative_tax_protection)/SQRT(N) -> 17051.555 | BU2: 95%CI_HB | BV2: =avg_tax_protection+1.96*STDEV(accumulative_tax_protection)/SQRT(N) -> 17225.865
K3: population | L3: 100 | O3: 2 | P3: =(1-p_encounter*p_infected)^R3 -> 0.63399099 | Q3: =_xlfn.BINOM.INV(S1_,p1_,RAND()) -> 82 | R3: =_xlfn.BINOM.INV(I1_,1-p_die,RAND())+Q2-Q3 -> 18 | S3: =100-Q3-R3 -> 0 | V3: infection_rate | W3: =($R$101+$S$101)/100 -> 1 | Z3: 2 | AA3: 1 | AB3: 1 | AC3: 1 | AD3: 13910 | AG3: Qc | AH3: avg_infection_rate | AI3: =AVERAGE(r_infection) -> 1 | AJ3: 95%CI_LB | AK3: =AI3-1.96*STDEV(r_infection)/SQRT(N) -> 1 | AL3: 95%CI_HB | AM3: =AI3+1.96*STDEV(r_infection)/SQRT(N) -> 1 | AP3: 2 | AQ3: =(1-p_encounter_protection*p_infected_protection)^AS3 -> 0.96069304 | AR3: =_xlfn.BINOM.INV(S1_,p1_protection,RAND()) -> 92 | AS3: =_xlfn.BINOM.INV(I1_,1-p_die,RAND())+AR2-AR3 -> 8 | AT3: =100-AR3-AS3 -> 0 | AW3: infection_rate | AX3: =($AS$101+$AT$101)/100 -> 1 | BA3: 2 | BB3: 1 | BC3: 0 | BD3: 0.99 | BE3: 17010 | BI3: avg_infection_rate_protection | BJ3: =AVERAGE(r_infection_protection) -> 0.99352 | BK3: 95%CI_LB | BL3: =BJ3-1.96*STDEV(r_infection_protection)/SQRT(N) -> 0.99293037 | BM3: 95%CI_HB | BN3: =avg_infection_rate_protection+1.96*STDEV(r_infection_protection)/SQRT(N) -> 0.99410963 | BQ3: gain ($000s) | BR3: =avg_tax_protection-avg_tax_no_protection -> 4530.34
A4: INPUT — Model Parameters | K4: p(encounter) | L4: 0.05 | O4: 3 | P4: =(1-p_encounter*p_infected)^R4 -> 0.2819881 | Q4: =IF(R3=0,Q3,_xlfn.BINOM.INV(Q3,P3,RAND())) -> 47 | R4: =IF(R3>0,_xlfn.BINOM.INV(R3,1-p_die,RAND()),0)+(Q3-Q4) -> 50 | S4: =100-Q4-R4 -> 3 | V4: accumulative_tax ($000s) | W4: =10*(SUM(St)+SUM(It)) -> 11320 | Z4: 3 | AA4: 1 | AB4: 1 | AC4: 1 | AD4: 11980 | AP4: 3 | AQ4: =(1-p_encounter_protection*p_infected_protection)^AS4 -> 0.94162281 | AR4: =IF(AS3=0,AR3,_xlfn.BINOM.INV(AR3,AQ3,RAND())) -> 88 | AS4: =IF(AS3>0,_xlfn.BINOM.INV(AS3,1-p_die,RAND()),0)+(AR3-AR4) -> 12 | AT4: =100-AR4-AS4 -> 0 | AW4: accumulative_tax ($000s) | AX4: =10*(SUM(St_protection)+SUM(It_protection)) -> 17590 | BA4: 3 | BB4: 1 | BC4: 1 | BD4: 1 | BE4: 15500
A5: Defines the initial village state and stochastic parameters. The village starts with 95 susceptible and 5 infected residents. Encounter probability is 5%; conditional infection probability is 50% without protection and 10% with protection; infected mortality is 10% per period. N = 1,000 is the number of simulated villages. | K5: p(encounter_protection) | L5: 0.05 | O5: 4 | P5: =(1-p_encounter*p_infected)^R5 -> 0.14234932 | Q5: =IF(R4=0,Q4,_xlfn.BINOM.INV(Q4,P4,RAND())) -> 13 | R5: =IF(R4>0,_xlfn.BINOM.INV(R4,1-p_die,RAND()),0)+(Q4-Q5) -> 77 | S5: =100-Q5-R5 -> 10 | Z5: 4 | AA5: 1 | AB5: 1 | AC5: 1 | AD5: 13570 | AP5: 4 | AQ5: =(1-p_encounter_protection*p_infected_protection)^AS5 -> 0.90915626 | AR5: =IF(AS4=0,AR4,_xlfn.BINOM.INV(AR4,AQ4,RAND())) -> 81 | AS5: =IF(AS4>0,_xlfn.BINOM.INV(AS4,1-p_die,RAND()),0)+(AR4-AR5) -> 19 | AT5: =100-AR5-AS5 -> 0 | BA5: 4 | BB5: 1 | BC5: 1 | BD5: 1 | BE5: 14820
K6: p(infected) | L6: 0.5 | O6: 5 | P6: =(1-p_encounter*p_infected)^R6 -> 0.12228779 | Q6: =IF(R5=0,Q5,_xlfn.BINOM.INV(Q5,P5,RAND())) -> 1 | R6: =IF(R5>0,_xlfn.BINOM.INV(R5,1-p_die,RAND()),0)+(Q5-Q6) -> 83 | S6: =100-Q6-R6 -> 16 | Z6: 5 | AA6: 1 | AB6: 1 | AC6: 1 | AD6: 11060 | AP6: 5 | AQ6: =(1-p_encounter_protection*p_infected_protection)^AS6 -> 0.87780914 | AR6: =IF(AS5=0,AR5,_xlfn.BINOM.INV(AR5,AQ5,RAND())) -> 72 | AS6: =IF(AS5>0,_xlfn.BINOM.INV(AS5,1-p_die,RAND()),0)+(AR5-AR6) -> 26 | AT6: =100-AR6-AS6 -> 2 | BA6: 5 | BB6: 1 | BC6: 1 | BD6: 1 | BE6: 16610
K7: p(infected_protection) | L7: 0.1 | O7: 6 | P7: =(1-p_encounter*p_infected)^R7 -> 0.16155944 | Q7: =IF(R6=0,Q6,_xlfn.BINOM.INV(Q6,P6,RAND())) -> 0 | R7: =IF(R6>0,_xlfn.BINOM.INV(R6,1-p_die,RAND()),0)+(Q6-Q7) -> 72 | S7: =100-Q7-R7 -> 28 | Z7: 6 | AA7: 1 | AB7: 1 | AC7: 1 | AD7: 12550 | AP7: 6 | AQ7: =(1-p_encounter_protection*p_infected_protection)^AS7 -> 0.85608227 | AR7: =IF(AS6=0,AR6,_xlfn.BINOM.INV(AR6,AQ6,RAND())) -> 66 | AS7: =IF(AS6>0,_xlfn.BINOM.INV(AS6,1-p_die,RAND()),0)+(AR6-AR7) -> 31 | AT7: =100-AR7-AS7 -> 3 | BA7: 6 | BB7: 1 | BC7: 0 | BD7: 0.99 | BE7: 17360
K8: p(die) | L8: 0.1 | O8: 7 | P8: =(1-p_encounter*p_infected)^R8 -> 0.1928857 | Q8: =IF(R7=0,Q7,_xlfn.BINOM.INV(Q7,P7,RAND())) -> 0 | R8: =IF(R7>0,_xlfn.BINOM.INV(R7,1-p_die,RAND()),0)+(Q7-Q8) -> 65 | S8: =100-Q8-R8 -> 35 | Z8: 7 | AA8: 1 | AB8: 1 | AC8: 1 | AD8: 12980 | AP8: 7 | AQ8: =(1-p_encounter_protection*p_infected_protection)^AS8 -> 0.86470773 | AR8: =IF(AS7=0,AR7,_xlfn.BINOM.INV(AR7,AQ7,RAND())) -> 63 | AS8: =IF(AS7>0,_xlfn.BINOM.INV(AS7,1-p_die,RAND()),0)+(AR7-AR8) -> 29 | AT8: =100-AR8-AS8 -> 8 | BA8: 7 | BB8: 1 | BC8: 1 | BD8: 1 | BE8: 17420
K9: p1 | L9: =(1-p_encounter*p_infected)^I1_ -> 0.88109569 | O9: 8 | P9: =(1-p_encounter*p_infected)^R9 -> 0.23028609 | Q9: =IF(R8=0,Q8,_xlfn.BINOM.INV(Q8,P8,RAND())) -> 0 | R9: =IF(R8>0,_xlfn.BINOM.INV(R8,1-p_die,RAND()),0)+(Q8-Q9) -> 58 | S9: =100-Q9-R9 -> 42 | Z9: 8 | AA9: 1 | AB9: 1 | AC9: 1 | AD9: 14160 | AP9: 8 | AQ9: =(1-p_encounter_protection*p_infected_protection)^AS9 -> 0.84330514 | AR9: =IF(AS8=0,AR8,_xlfn.BINOM.INV(AR8,AQ8,RAND())) -> 53 | AS9: =IF(AS8>0,_xlfn.BINOM.INV(AS8,1-p_die,RAND()),0)+(AR8-AR9) -> 34 | AT9: =100-AR9-AS9 -> 13 | BA9: 8 | BB9: 1 | BC9: 1 | BD9: 1 | BE9: 16330
A10: SAMPLE PATH — No Protection | K10: p1_protection | L10: =(1-p_encounter_protection*p_infected_protection)^I1_ -> 0.97524875 | O10: 9 | P10: =(1-p_encounter*p_infected)^R10 -> 0.24224704 | Q10: =IF(R9=0,Q9,_xlfn.BINOM.INV(Q9,P9,RAND())) -> 0 | R10: =IF(R9>0,_xlfn.BINOM.INV(R9,1-p_die,RAND()),0)+(Q9-Q10) -> 56 | S10: =100-Q10-R10 -> 44 | Z10: 9 | AA10: 1 | AB10: 1 | AC10: 1 | AD10: 12350 | AP10: 9 | AQ10: =(1-p_encounter_protection*p_infected_protection)^AS10 -> 0.80610659 | AR10: =IF(AS9=0,AR9,_xlfn.BINOM.INV(AR9,AQ9,RAND())) -> 43 | AS10: =IF(AS9>0,_xlfn.BINOM.INV(AS9,1-p_die,RAND()),0)+(AR9-AR10) -> 43 | AT10: =100-AR10-AS10 -> 14 | BA10: 9 | BB10: 1 | BC10: 1 | BD10: 1 | BE10: 16210
A11: Columns F:J trace one stochastic 100-period village trajectory. For each period, p_t is the probability that a susceptible avoids infection from all current infectives. St is the susceptible population, It the infected population, and Dt cumulative deaths. Each next state is generated with binomial random draws, so recalculation can produce a different path. | K11: N | L11: 1000 | O11: 10 | P11: =(1-p_encounter*p_infected)^R11 -> 0.29663443 | Q11: =IF(R10=0,Q10,_xlfn.BINOM.INV(Q10,P10,RAND())) -> 0 | R11: =IF(R10>0,_xlfn.BINOM.INV(R10,1-p_die,RAND()),0)+(Q10-Q11) -> 48 | S11: =100-Q11-R11 -> 52 | Z11: 10 | AA11: 1 | AB11: 1 | AC11: 1 | AD11: 12740 | AP11: 10 | AQ11: =(1-p_encounter_protection*p_infected_protection)^AS11 -> 0.79407535 | AR11: =IF(AS10=0,AR10,_xlfn.BINOM.INV(AR10,AQ10,RAND())) -> 33 | AS11: =IF(AS10>0,_xlfn.BINOM.INV(AS10,1-p_die,RAND()),0)+(AR10-AR11) -> 46 | AT11: =100-AR11-AS11 -> 21 | BA11: 10 | BB11: 1 | BC11: 0 | BD11: 0.99 | BE11: 16180
O12: 11 | P12: =(1-p_encounter*p_infected)^R12 -> 0.36323244 | Q12: =IF(R11=0,Q11,_xlfn.BINOM.INV(Q11,P11,RAND())) -> 0 | R12: =IF(R11>0,_xlfn.BINOM.INV(R11,1-p_die,RAND()),0)+(Q11-Q12) -> 40 | S12: =100-Q12-R12 -> 60 | Z12: 11 | AA12: 1 | AB12: 1 | AC12: 1 | AD12: 12930 | AP12: 11 | AQ12: =(1-p_encounter_protection*p_infected_protection)^AS12 -> 0.80610659 | AR12: =IF(AS11=0,AR11,_xlfn.BINOM.INV(AR11,AQ11,RAND())) -> 27 | AS12: =IF(AS11>0,_xlfn.BINOM.INV(AS11,1-p_die,RAND()),0)+(AR11-AR12) -> 43 | AT12: =100-AR12-AS12 -> 30 | BA12: 11 | BB12: 1 | BC12: 1 | BD12: 1 | BE12: 14430
O13: 12 | P13: =(1-p_encounter*p_infected)^R13 -> 0.45618719 | Q13: =IF(R12=0,Q12,_xlfn.BINOM.INV(Q12,P12,RAND())) -> 0 | R13: =IF(R12>0,_xlfn.BINOM.INV(R12,1-p_die,RAND()),0)+(Q12-Q13) -> 31 | S13: =100-Q13-R13 -> 69 | Z13: 12 | AA13: 1 | AB13: 1 | AC13: 1 | AD13: 13800 | AP13: 12 | AQ13: =(1-p_encounter_protection*p_infected_protection)^AS13 -> 0.79407535 | AR13: =IF(AS12=0,AR12,_xlfn.BINOM.INV(AR12,AQ12,RAND())) -> 22 | AS13: =IF(AS12>0,_xlfn.BINOM.INV(AS12,1-p_die,RAND()),0)+(AR12-AR13) -> 46 | AT13: =100-AR13-AS13 -> 32 | BA13: 12 | BB13: 1 | BC13: 0 | BD13: 0.96 | BE13: 16760
O14: 13 | P14: =(1-p_encounter*p_infected)^R14 -> 0.47988133 | Q14: =IF(R13=0,Q13,_xlfn.BINOM.INV(Q13,P13,RAND())) -> 0 | R14: =IF(R13>0,_xlfn.BINOM.INV(R13,1-p_die,RAND()),0)+(Q13-Q14) -> 29 | S14: =100-Q14-R14 -> 71 | Z14: 13 | AA14: 1 | AB14: 1 | AC14: 1 | AD14: 14090 | AP14: 13 | AQ14: =(1-p_encounter_protection*p_infected_protection)^AS14 -> 0.78222368 | AR14: =IF(AS13=0,AR13,_xlfn.BINOM.INV(AR13,AQ13,RAND())) -> 17 | AS14: =IF(AS13>0,_xlfn.BINOM.INV(AS13,1-p_die,RAND()),0)+(AR13-AR14) -> 49 | AT14: =100-AR14-AS14 -> 34 | BA14: 13 | BB14: 1 | BC14: 0 | BD14: 0.98 | BE14: 17500
O15: 14 | P15: =(1-p_encounter*p_infected)^R15 -> 0.51774988 | Q15: =IF(R14=0,Q14,_xlfn.BINOM.INV(Q14,P14,RAND())) -> 0 | R15: =IF(R14>0,_xlfn.BINOM.INV(R14,1-p_die,RAND()),0)+(Q14-Q15) -> 26 | S15: =100-Q15-R15 -> 74 | Z15: 14 | AA15: 1 | AB15: 1 | AC15: 1 | AD15: 11740 | AP15: 14 | AQ15: =(1-p_encounter_protection*p_infected_protection)^AS15 -> 0.77442099 | AR15: =IF(AS14=0,AR14,_xlfn.BINOM.INV(AR14,AQ14,RAND())) -> 10 | AS15: =IF(AS14>0,_xlfn.BINOM.INV(AS14,1-p_die,RAND()),0)+(AR14-AR15) -> 51 | AT15: =100-AR15-AS15 -> 39 | BA15: 14 | BB15: 1 | BC15: 0 | BD15: 0.99 | BE15: 17530
O16: 15 | P16: =(1-p_encounter*p_infected)^R16 -> 0.53102552 | Q16: =IF(R15=0,Q15,_xlfn.BINOM.INV(Q15,P15,RAND())) -> 0 | R16: =IF(R15>0,_xlfn.BINOM.INV(R15,1-p_die,RAND()),0)+(Q15-Q16) -> 25 | S16: =100-Q16-R16 -> 75 | Z16: 15 | AA16: 1 | AB16: 1 | AC16: 1 | AD16: 10460 | AP16: 15 | AQ16: =(1-p_encounter_protection*p_infected_protection)^AS16 -> 0.80207606 | AR16: =IF(AS15=0,AR15,_xlfn.BINOM.INV(AR15,AQ15,RAND())) -> 7 | AS16: =IF(AS15>0,_xlfn.BINOM.INV(AS15,1-p_die,RAND()),0)+(AR15-AR16) -> 44 | AT16: =100-AR16-AS16 -> 49 | BA16: 15 | BB16: 1 | BC16: 1 | BD16: 1 | BE16: 17150
A17: STAT — What the Four Values Mean | O17: 16 | P17: =(1-p_encounter*p_infected)^R17 -> 0.54464156 | Q17: =IF(R16=0,Q16,_xlfn.BINOM.INV(Q16,P16,RAND())) -> 0 | R17: =IF(R16>0,_xlfn.BINOM.INV(R16,1-p_die,RAND()),0)+(Q16-Q17) -> 24 | S17: =100-Q17-R17 -> 76 | Z17: 16 | AA17: 1 | AB17: 1 | AC17: 1 | AD17: 12640 | AP17: 16 | AQ17: =(1-p_encounter_protection*p_infected_protection)^AS17 -> 0.81015738 | AR17: =IF(AS16=0,AR16,_xlfn.BINOM.INV(AR16,AQ16,RAND())) -> 6 | AS17: =IF(AS16>0,_xlfn.BINOM.INV(AS16,1-p_die,RAND()),0)+(AR16-AR17) -> 42 | AT17: =100-AR17-AS17 -> 52 | BA17: 16 | BB17: 1 | BC17: 0 | BD17: 0.97 | BE17: 18980
A18: The STAT block converts the final state of one sample path into four analysis-ready outcomes: disease_dieout = 1 when I₁₀₀ = 0; population_dieout = 1 when D₁₀₀ = 100; infection_rate is the share of the original population ever infected by period 100; accumulative_tax is cumulative tax generated by living residents, reported in $000s. These values feed the Monte Carlo Data Table. | O18: 17 | P18: =(1-p_encounter*p_infected)^R18 -> 0.60268768 | Q18: =IF(R17=0,Q17,_xlfn.BINOM.INV(Q17,P17,RAND())) -> 0 | R18: =IF(R17>0,_xlfn.BINOM.INV(R17,1-p_die,RAND()),0)+(Q17-Q18) -> 20 | S18: =100-Q18-R18 -> 80 | Z18: 17 | AA18: 1 | AB18: 1 | AC18: 1 | AD18: 11730 | AP18: 17 | AQ18: =(1-p_encounter_protection*p_infected_protection)^AS18 -> 0.81832012 | AR18: =IF(AS17=0,AR17,_xlfn.BINOM.INV(AR17,AQ17,RAND())) -> 4 | AS18: =IF(AS17>0,_xlfn.BINOM.INV(AS17,1-p_die,RAND()),0)+(AR17-AR18) -> 40 | AT18: =100-AR18-AS18 -> 56 | BA18: 17 | BB18: 1 | BC18: 1 | BD18: 1 | BE18: 14900
O19: 18 | P19: =(1-p_encounter*p_infected)^R19 -> 0.66692017 | Q19: =IF(R18=0,Q18,_xlfn.BINOM.INV(Q18,P18,RAND())) -> 0 | R19: =IF(R18>0,_xlfn.BINOM.INV(R18,1-p_die,RAND()),0)+(Q18-Q19) -> 16 | S19: =100-Q19-R19 -> 84 | Z19: 18 | AA19: 1 | AB19: 1 | AC19: 1 | AD19: 12550 | AP19: 18 | AQ19: =(1-p_encounter_protection*p_infected_protection)^AS19 -> 0.8307187 | AR19: =IF(AS18=0,AR18,_xlfn.BINOM.INV(AR18,AQ18,RAND())) -> 4 | AS19: =IF(AS18>0,_xlfn.BINOM.INV(AS18,1-p_die,RAND()),0)+(AR18-AR19) -> 37 | AT19: =100-AR19-AS19 -> 59 | BA19: 18 | BB19: 1 | BC19: 1 | BD19: 1 | BE19: 16090
O20: 19 | P20: =(1-p_encounter*p_infected)^R20 -> 0.70155968 | Q20: =IF(R19=0,Q19,_xlfn.BINOM.INV(Q19,P19,RAND())) -> 0 | R20: =IF(R19>0,_xlfn.BINOM.INV(R19,1-p_die,RAND()),0)+(Q19-Q20) -> 14 | S20: =100-Q20-R20 -> 86 | Z20: 19 | AA20: 1 | AB20: 1 | AC20: 1 | AD20: 13280 | AP20: 19 | AQ20: =(1-p_encounter_protection*p_infected_protection)^AS20 -> 0.84330514 | AR20: =IF(AS19=0,AR19,_xlfn.BINOM.INV(AR19,AQ19,RAND())) -> 3 | AS20: =IF(AS19>0,_xlfn.BINOM.INV(AS19,1-p_die,RAND()),0)+(AR19-AR20) -> 34 | AT20: =100-AR20-AS20 -> 63 | BA20: 19 | BB20: 1 | BC20: 1 | BD20: 1 | BE20: 17110
O21: 20 | P21: =(1-p_encounter*p_infected)^R21 -> 0.70155968 | Q21: =IF(R20=0,Q20,_xlfn.BINOM.INV(Q20,P20,RAND())) -> 0 | R21: =IF(R20>0,_xlfn.BINOM.INV(R20,1-p_die,RAND()),0)+(Q20-Q21) -> 14 | S21: =100-Q21-R21 -> 86 | Z21: 20 | AA21: 1 | AB21: 1 | AC21: 1 | AD21: 11230 | AP21: 20 | AQ21: =(1-p_encounter_protection*p_infected_protection)^AS21 -> 0.83908861 | AR21: =IF(AS20=0,AR20,_xlfn.BINOM.INV(AR20,AQ20,RAND())) -> 1 | AS21: =IF(AS20>0,_xlfn.BINOM.INV(AS20,1-p_die,RAND()),0)+(AR20-AR21) -> 35 | AT21: =100-AR21-AS21 -> 64 | BA21: 20 | BB21: 1 | BC21: 1 | BD21: 1 | BE21: 16560
O22: 21 | P22: =(1-p_encounter*p_infected)^R22 -> 0.71954839 | Q22: =IF(R21=0,Q21,_xlfn.BINOM.INV(Q21,P21,RAND())) -> 0 | R22: =IF(R21>0,_xlfn.BINOM.INV(R21,1-p_die,RAND()),0)+(Q21-Q22) -> 13 | S22: =100-Q22-R22 -> 87 | Z22: 21 | AA22: 1 | AB22: 1 | AC22: 1 | AD22: 11940 | AP22: 21 | AQ22: =(1-p_encounter_protection*p_infected_protection)^AS22 -> 0.85180186 | AR22: =IF(AS21=0,AR21,_xlfn.BINOM.INV(AR21,AQ21,RAND())) -> 0 | AS22: =IF(AS21>0,_xlfn.BINOM.INV(AS21,1-p_die,RAND()),0)+(AR21-AR22) -> 32 | AT22: =100-AR22-AS22 -> 68 | BA22: 21 | BB22: 1 | BC22: 0 | BD22: 0.98 | BE22: 16200
O23: 22 | P23: =(1-p_encounter*p_infected)^R23 -> 0.73799835 | Q23: =IF(R22=0,Q22,_xlfn.BINOM.INV(Q22,P22,RAND())) -> 0 | R23: =IF(R22>0,_xlfn.BINOM.INV(R22,1-p_die,RAND()),0)+(Q22-Q23) -> 12 | S23: =100-Q23-R23 -> 88 | Z23: 22 | AA23: 1 | AB23: 1 | AC23: 1 | AD23: 12800 | AP23: 22 | AQ23: =(1-p_encounter_protection*p_infected_protection)^AS23 -> 0.86470773 | AR23: =IF(AS22=0,AR22,_xlfn.BINOM.INV(AR22,AQ22,RAND())) -> 0 | AS23: =IF(AS22>0,_xlfn.BINOM.INV(AS22,1-p_die,RAND()),0)+(AR22-AR23) -> 29 | AT23: =100-AR23-AS23 -> 71 | BA23: 22 | BB23: 1 | BC23: 1 | BD23: 1 | BE23: 17030
A24: DATA TABLE — 1,000 Villages | O24: 23 | P24: =(1-p_encounter*p_infected)^R24 -> 0.73799835 | Q24: =IF(R23=0,Q23,_xlfn.BINOM.INV(Q23,P23,RAND())) -> 0 | R24: =IF(R23>0,_xlfn.BINOM.INV(R23,1-p_die,RAND()),0)+(Q23-Q24) -> 12 | S24: =100-Q24-R24 -> 88 | Z24: 23 | AA24: 1 | AB24: 1 | AC24: 1 | AD24: 12460 | AP24: 23 | AQ24: =(1-p_encounter_protection*p_infected_protection)^AS24 -> 0.88665351 | AR24: =IF(AS23=0,AR23,_xlfn.BINOM.INV(AR23,AQ23,RAND())) -> 0 | AS24: =IF(AS23>0,_xlfn.BINOM.INV(AS23,1-p_die,RAND()),0)+(AR23-AR24) -> 24 | AT24: =100-AR24-AS24 -> 76 | BA24: 23 | BB24: 1 | BC24: 1 | BD24: 1 | BE24: 18320
A25: The Data Table repeats the stochastic sample-path model 1,000 times. Each row is one simulated village and records the four STAT outcomes. The output section then averages these replications to estimate probabilities or expected values and uses the cross-village variation to construct 95% confidence intervals. | O25: 24 | P25: =(1-p_encounter*p_infected)^R25 -> 0.8166518 | Q25: =IF(R24=0,Q24,_xlfn.BINOM.INV(Q24,P24,RAND())) -> 0 | R25: =IF(R24>0,_xlfn.BINOM.INV(R24,1-p_die,RAND()),0)+(Q24-Q25) -> 8 | S25: =100-Q25-R25 -> 92 | Z25: 24 | AA25: 1 | AB25: 1 | AC25: 1 | AD25: 11920 | AP25: 24 | AQ25: =(1-p_encounter_protection*p_infected_protection)^AS25 -> 0.89110906 | AR25: =IF(AS24=0,AR24,_xlfn.BINOM.INV(AR24,AQ24,RAND())) -> 0 | AS25: =IF(AS24>0,_xlfn.BINOM.INV(AS24,1-p_die,RAND()),0)+(AR24-AR25) -> 23 | AT25: =100-AR25-AS25 -> 77 | BA25: 24 | BB25: 1 | BC25: 1 | BD25: 1 | BE25: 14360
O26: 25 | P26: =(1-p_encounter*p_infected)^R26 -> 0.83759159 | Q26: =IF(R25=0,Q25,_xlfn.BINOM.INV(Q25,P25,RAND())) -> 0 | R26: =IF(R25>0,_xlfn.BINOM.INV(R25,1-p_die,RAND()),0)+(Q25-Q26) -> 7 | S26: =100-Q26-R26 -> 93 | Z26: 25 | AA26: 1 | AB26: 1 | AC26: 1 | AD26: 11740 | AP26: 25 | AQ26: =(1-p_encounter_protection*p_infected_protection)^AS26 -> 0.89558699 | AR26: =IF(AS25=0,AR25,_xlfn.BINOM.INV(AR25,AQ25,RAND())) -> 0 | AS26: =IF(AS25>0,_xlfn.BINOM.INV(AS25,1-p_die,RAND()),0)+(AR25-AR26) -> 22 | AT26: =100-AR26-AS26 -> 78 | BA26: 25 | BB26: 1 | BC26: 0 | BD26: 0.99 | BE26: 15820
O27: 26 | P27: =(1-p_encounter*p_infected)^R27 -> 0.83759159 | Q27: =IF(R26=0,Q26,_xlfn.BINOM.INV(Q26,P26,RAND())) -> 0 | R27: =IF(R26>0,_xlfn.BINOM.INV(R26,1-p_die,RAND()),0)+(Q26-Q27) -> 7 | S27: =100-Q27-R27 -> 93 | Z27: 26 | AA27: 1 | AB27: 1 | AC27: 1 | AD27: 12070 | AP27: 26 | AQ27: =(1-p_encounter_protection*p_infected_protection)^AS27 -> 0.90461048 | AR27: =IF(AS26=0,AR26,_xlfn.BINOM.INV(AR26,AQ26,RAND())) -> 0 | AS27: =IF(AS26>0,_xlfn.BINOM.INV(AS26,1-p_die,RAND()),0)+(AR26-AR27) -> 20 | AT27: =100-AR27-AS27 -> 80 | BA27: 26 | BB27: 1 | BC27: 1 | BD27: 1 | BE27: 16700
O28: 27 | P28: =(1-p_encounter*p_infected)^R28 -> 0.83759159 | Q28: =IF(R27=0,Q27,_xlfn.BINOM.INV(Q27,P27,RAND())) -> 0 | R28: =IF(R27>0,_xlfn.BINOM.INV(R27,1-p_die,RAND()),0)+(Q27-Q28) -> 7 | S28: =100-Q28-R28 -> 93 | Z28: 27 | AA28: 1 | AB28: 1 | AC28: 1 | AD28: 13370 | AP28: 27 | AQ28: =(1-p_encounter_protection*p_infected_protection)^AS28 -> 0.90461048 | AR28: =IF(AS27=0,AR27,_xlfn.BINOM.INV(AR27,AQ27,RAND())) -> 0 | AS28: =IF(AS27>0,_xlfn.BINOM.INV(AS27,1-p_die,RAND()),0)+(AR27-AR28) -> 20 | AT28: =100-AR28-AS28 -> 80 | BA28: 27 | BB28: 1 | BC28: 1 | BD28: 1 | BE28: 16150
O29: 28 | P29: =(1-p_encounter*p_infected)^R29 -> 0.88109569 | Q29: =IF(R28=0,Q28,_xlfn.BINOM.INV(Q28,P28,RAND())) -> 0 | R29: =IF(R28>0,_xlfn.BINOM.INV(R28,1-p_die,RAND()),0)+(Q28-Q29) -> 5 | S29: =100-Q29-R29 -> 95 | Z29: 28 | AA29: 1 | AB29: 1 | AC29: 1 | AD29: 13730 | AP29: 28 | AQ29: =(1-p_encounter_protection*p_infected_protection)^AS29 -> 0.91831647 | AR29: =IF(AS28=0,AR28,_xlfn.BINOM.INV(AR28,AQ28,RAND())) -> 0 | AS29: =IF(AS28>0,_xlfn.BINOM.INV(AS28,1-p_die,RAND()),0)+(AR28-AR29) -> 17 | AT29: =100-AR29-AS29 -> 83 | BA29: 28 | BB29: 1 | BC29: 0 | BD29: 0.98 | BE29: 16690
O30: 29 | P30: =(1-p_encounter*p_infected)^R30 -> 0.88109569 | Q30: =IF(R29=0,Q29,_xlfn.BINOM.INV(Q29,P29,RAND())) -> 0 | R30: =IF(R29>0,_xlfn.BINOM.INV(R29,1-p_die,RAND()),0)+(Q29-Q30) -> 5 | S30: =100-Q30-R30 -> 95 | Z30: 29 | AA30: 1 | AB30: 1 | AC30: 1 | AD30: 12470 | AP30: 29 | AQ30: =(1-p_encounter_protection*p_infected_protection)^AS30 -> 0.92756897 | AR30: =IF(AS29=0,AR29,_xlfn.BINOM.INV(AR29,AQ29,RAND())) -> 0 | AS30: =IF(AS29>0,_xlfn.BINOM.INV(AS29,1-p_die,RAND()),0)+(AR29-AR30) -> 15 | AT30: =100-AR30-AS30 -> 85 | BA30: 29 | BB30: 1 | BC30: 1 | BD30: 1 | BE30: 16420
A31: Qa — Population Die-Out Risk | O31: 30 | P31: =(1-p_encounter*p_infected)^R31 -> 0.90368789 | Q31: =IF(R30=0,Q30,_xlfn.BINOM.INV(Q30,P30,RAND())) -> 0 | R31: =IF(R30>0,_xlfn.BINOM.INV(R30,1-p_die,RAND()),0)+(Q30-Q31) -> 4 | S31: =100-Q31-R31 -> 96 | Z31: 30 | AA31: 1 | AB31: 1 | AC31: 1 | AD31: 11570 | AP31: 30 | AQ31: =(1-p_encounter_protection*p_infected_protection)^AS31 -> 0.93691469 | AR31: =IF(AS30=0,AR30,_xlfn.BINOM.INV(AR30,AQ30,RAND())) -> 0 | AS31: =IF(AS30>0,_xlfn.BINOM.INV(AS30,1-p_die,RAND()),0)+(AR30-AR31) -> 13 | AT31: =100-AR31-AS31 -> 87 | BA31: 30 | BB31: 1 | BC31: 0 | BD31: 0.99 | BE31: 17960
A32: Qa estimates the probability that the entire original population has died by period 100 under no protection. It addresses the most severe population-level consequence of the epidemic: catastrophic village loss. The reported 95% confidence interval quantifies Monte Carlo uncertainty around this estimated probability. | O32: 31 | P32: =(1-p_encounter*p_infected)^R32 -> 0.92685938 | Q32: =IF(R31=0,Q31,_xlfn.BINOM.INV(Q31,P31,RAND())) -> 0 | R32: =IF(R31>0,_xlfn.BINOM.INV(R31,1-p_die,RAND()),0)+(Q31-Q32) -> 3 | S32: =100-Q32-R32 -> 97 | Z32: 31 | AA32: 1 | AB32: 1 | AC32: 1 | AD32: 13320 | AP32: 31 | AQ32: =(1-p_encounter_protection*p_infected_protection)^AS32 -> 0.94635458 | AR32: =IF(AS31=0,AR31,_xlfn.BINOM.INV(AR31,AQ31,RAND())) -> 0 | AS32: =IF(AS31>0,_xlfn.BINOM.INV(AS31,1-p_die,RAND()),0)+(AR31-AR32) -> 11 | AT32: =100-AR32-AS32 -> 89 | BA32: 31 | BB32: 1 | BC32: 1 | BD32: 1 | BE32: 18290
O33: 32 | P33: =(1-p_encounter*p_infected)^R33 -> 0.92685938 | Q33: =IF(R32=0,Q32,_xlfn.BINOM.INV(Q32,P32,RAND())) -> 0 | R33: =IF(R32>0,_xlfn.BINOM.INV(R32,1-p_die,RAND()),0)+(Q32-Q33) -> 3 | S33: =100-Q33-R33 -> 97 | Z33: 32 | AA33: 1 | AB33: 1 | AC33: 1 | AD33: 11230 | AP33: 32 | AQ33: =(1-p_encounter_protection*p_infected_protection)^AS33 -> 0.95111013 | AR33: =IF(AS32=0,AR32,_xlfn.BINOM.INV(AR32,AQ32,RAND())) -> 0 | AS33: =IF(AS32>0,_xlfn.BINOM.INV(AS32,1-p_die,RAND()),0)+(AR32-AR33) -> 10 | AT33: =100-AR33-AS33 -> 90 | BA33: 32 | BB33: 1 | BC33: 1 | BD33: 1 | BE33: 16150
O34: 33 | P34: =(1-p_encounter*p_infected)^R34 -> 0.92685938 | Q34: =IF(R33=0,Q33,_xlfn.BINOM.INV(Q33,P33,RAND())) -> 0 | R34: =IF(R33>0,_xlfn.BINOM.INV(R33,1-p_die,RAND()),0)+(Q33-Q34) -> 3 | S34: =100-Q34-R34 -> 97 | Z34: 33 | AA34: 1 | AB34: 1 | AC34: 1 | AD34: 13080 | AP34: 33 | AQ34: =(1-p_encounter_protection*p_infected_protection)^AS34 -> 0.95111013 | AR34: =IF(AS33=0,AR33,_xlfn.BINOM.INV(AR33,AQ33,RAND())) -> 0 | AS34: =IF(AS33>0,_xlfn.BINOM.INV(AS33,1-p_die,RAND()),0)+(AR33-AR34) -> 10 | AT34: =100-AR34-AS34 -> 90 | BA34: 33 | BB34: 1 | BC34: 1 | BD34: 1 | BE34: 15260
O35: 34 | P35: =(1-p_encounter*p_infected)^R35 -> 0.92685938 | Q35: =IF(R34=0,Q34,_xlfn.BINOM.INV(Q34,P34,RAND())) -> 0 | R35: =IF(R34>0,_xlfn.BINOM.INV(R34,1-p_die,RAND()),0)+(Q34-Q35) -> 3 | S35: =100-Q35-R35 -> 97 | Z35: 34 | AA35: 1 | AB35: 1 | AC35: 1 | AD35: 14110 | AP35: 34 | AQ35: =(1-p_encounter_protection*p_infected_protection)^AS35 -> 0.96069304 | AR35: =IF(AS34=0,AR34,_xlfn.BINOM.INV(AR34,AQ34,RAND())) -> 0 | AS35: =IF(AS34>0,_xlfn.BINOM.INV(AS34,1-p_die,RAND()),0)+(AR34-AR35) -> 8 | AT35: =100-AR35-AS35 -> 92 | BA35: 34 | BB35: 1 | BC35: 1 | BD35: 1 | BE35: 16290
O36: 35 | P36: =(1-p_encounter*p_infected)^R36 -> 0.92685938 | Q36: =IF(R35=0,Q35,_xlfn.BINOM.INV(Q35,P35,RAND())) -> 0 | R36: =IF(R35>0,_xlfn.BINOM.INV(R35,1-p_die,RAND()),0)+(Q35-Q36) -> 3 | S36: =100-Q36-R36 -> 97 | Z36: 35 | AA36: 1 | AB36: 1 | AC36: 1 | AD36: 11340 | AP36: 35 | AQ36: =(1-p_encounter_protection*p_infected_protection)^AS36 -> 0.96069304 | AR36: =IF(AS35=0,AR35,_xlfn.BINOM.INV(AR35,AQ35,RAND())) -> 0 | AS36: =IF(AS35>0,_xlfn.BINOM.INV(AS35,1-p_die,RAND()),0)+(AR35-AR36) -> 8 | AT36: =100-AR36-AS36 -> 92 | BA36: 35 | BB36: 1 | BC36: 0 | BD36: 0.99 | BE36: 19070
O37: 36 | P37: =(1-p_encounter*p_infected)^R37 -> 0.92685938 | Q37: =IF(R36=0,Q36,_xlfn.BINOM.INV(Q36,P36,RAND())) -> 0 | R37: =IF(R36>0,_xlfn.BINOM.INV(R36,1-p_die,RAND()),0)+(Q36-Q37) -> 3 | S37: =100-Q37-R37 -> 97 | Z37: 36 | AA37: 1 | AB37: 1 | AC37: 1 | AD37: 13130 | AP37: 36 | AQ37: =(1-p_encounter_protection*p_infected_protection)^AS37 -> 0.97037251 | AR37: =IF(AS36=0,AR36,_xlfn.BINOM.INV(AR36,AQ36,RAND())) -> 0 | AS37: =IF(AS36>0,_xlfn.BINOM.INV(AS36,1-p_die,RAND()),0)+(AR36-AR37) -> 6 | AT37: =100-AR37-AS37 -> 94 | BA37: 36 | BB37: 1 | BC37: 1 | BD37: 1 | BE37: 16020
A38: Qb — Disease Die-Out Probability | O38: 37 | P38: =(1-p_encounter*p_infected)^R38 -> 0.92685938 | Q38: =IF(R37=0,Q37,_xlfn.BINOM.INV(Q37,P37,RAND())) -> 0 | R38: =IF(R37>0,_xlfn.BINOM.INV(R37,1-p_die,RAND()),0)+(Q37-Q38) -> 3 | S38: =100-Q38-R38 -> 97 | Z38: 37 | AA38: 1 | AB38: 1 | AC38: 1 | AD38: 14510 | AP38: 37 | AQ38: =(1-p_encounter_protection*p_infected_protection)^AS38 -> 0.97524875 | AR38: =IF(AS37=0,AR37,_xlfn.BINOM.INV(AR37,AQ37,RAND())) -> 0 | AS38: =IF(AS37>0,_xlfn.BINOM.INV(AS37,1-p_die,RAND()),0)+(AR37-AR38) -> 5 | AT38: =100-AR38-AS38 -> 95 | BA38: 37 | BB38: 1 | BC38: 1 | BD38: 1 | BE38: 19080
A39: Qb estimates the probability that no infected residents remain at period 100 under no protection. This is a terminal disease-status measure. It should be interpreted separately from population survival: the disease can disappear because transmission ends, but it can also disappear after causing extensive mortality. | O39: 38 | P39: =(1-p_encounter*p_infected)^R39 -> 0.92685938 | Q39: =IF(R38=0,Q38,_xlfn.BINOM.INV(Q38,P38,RAND())) -> 0 | R39: =IF(R38>0,_xlfn.BINOM.INV(R38,1-p_die,RAND()),0)+(Q38-Q39) -> 3 | S39: =100-Q39-R39 -> 97 | Z39: 38 | AA39: 1 | AB39: 1 | AC39: 1 | AD39: 13650 | AP39: 38 | AQ39: =(1-p_encounter_protection*p_infected_protection)^AS39 -> 0.97524875 | AR39: =IF(AS38=0,AR38,_xlfn.BINOM.INV(AR38,AQ38,RAND())) -> 0 | AS39: =IF(AS38>0,_xlfn.BINOM.INV(AS38,1-p_die,RAND()),0)+(AR38-AR39) -> 5 | AT39: =100-AR39-AS39 -> 95 | BA39: 38 | BB39: 1 | BC39: 1 | BD39: 1 | BE39: 15640
O40: 39 | P40: =(1-p_encounter*p_infected)^R40 -> 0.92685938 | Q40: =IF(R39=0,Q39,_xlfn.BINOM.INV(Q39,P39,RAND())) -> 0 | R40: =IF(R39>0,_xlfn.BINOM.INV(R39,1-p_die,RAND()),0)+(Q39-Q40) -> 3 | S40: =100-Q40-R40 -> 97 | Z40: 39 | AA40: 1 | AB40: 1 | AC40: 1 | AD40: 12200 | AP40: 39 | AQ40: =(1-p_encounter_protection*p_infected_protection)^AS40 -> 0.9801495 | AR40: =IF(AS39=0,AR39,_xlfn.BINOM.INV(AR39,AQ39,RAND())) -> 0 | AS40: =IF(AS39>0,_xlfn.BINOM.INV(AS39,1-p_die,RAND()),0)+(AR39-AR40) -> 4 | AT40: =100-AR40-AS40 -> 96 | BA40: 39 | BB40: 1 | BC40: 0 | BD40: 0.99 | BE40: 17670
...

Sheet 02_Results_Dashboard
A1: Simulation Results Dashboard
A3: 1,000 simulated villages • 100-period horizon • values linked directly to the original simulation model
A5: Outcome | B5: No Protection | C5: Protection | D5: Absolute Change | E5: No-Prot 95% LB | F5: No-Prot 95% UB | G5: Protection 95% CI
A6: Population die-out probability | B6: ='1Healthcare'!AI1 -> 0.993 | C6: ='1Healthcare'!BJ1 -> 0.56 | D6: =C6-B6 -> -0.433 | E6: ='1Healthcare'!AK1 -> 0.98782992 | F6: ='1Healthcare'!AM1 -> 0.99817008 | G6: =TEXT('1Healthcare'!BL1,"0.000")&" – "&TEXT('1Healthcare'!BN1,"0.000") -> 0.529 – 0.591
A7: Disease die-out probability | B7: ='1Healthcare'!AI2 -> 0.993 | C7: ='1Healthcare'!BJ2 -> 0.996 | D7: =C7-B7 -> 0.003 | E7: ='1Healthcare'!AK2 -> 0.98782992 | F7: ='1Healthcare'!AM2 -> 0.99817008 | G7: =TEXT('1Healthcare'!BL2,"0.000")&" – "&TEXT('1Healthcare'!BN2,"0.000") -> 0.992 – 1.000
A8: Average cumulative infection rate | B8: ='1Healthcare'!AI3 -> 1 | C8: ='1Healthcare'!BJ3 -> 0.99352 | D8: =C8-B8 -> -0.00648 | E8: ='1Healthcare'!AK3 -> 1 | F8: ='1Healthcare'!AM3 -> 1 | G8: =TEXT('1Healthcare'!BL3,"0.000")&" – "&TEXT('1Healthcare'!BN3,"0.000") -> 0.993 – 0.994
A9: Average cumulative tax ($000s) | B9: ='1Healthcare'!BR1 -> 12608.37 | C9: ='1Healthcare'!BR2 -> 17138.71 | D9: =C9-B9 -> 4530.34 | E9: ='1Healthcare'!BT1 -> 12548.105 | F9: ='1Healthcare'!BV1 -> 12668.635 | G9: =TEXT('1Healthcare'!BT2,"0.0")&" – "&TEXT('1Healthcare'!BV2,"0.0") -> 17051.6 – 17225.9
A12: Interpretation
A13: ="Across the 1,000-village Monte Carlo sample, protection changes the population die-out estimate from "&TEXT(B6,"0.0%")&" to "&TEXT(C6,"0.0%")&", a change of "&TEXT(D6,"0.0%")&". Disease extinction remains very high in both scenarios ("&TEXT(B7,"0.0%")&" vs. "&TEXT(C7,"0.0%")&"), showing why terminal disease status alone is not sufficient to evaluate the intervention. The average cumulative infection rate is "&TEXT(B8,"0.0%")&" without protection and "&TEXT(C8,"0.0%")&" with protection. Average cumulative tax revenue rises from $"&TEXT(B9/1000,"0.00")&"M to $"&TEXT(C9/1000,"0.00")&"M, an increase of about $"&TEXT(D9/1000,"0.00")&"M per simulated village over the horizon. The policy value in this model therefore comes primarily from preserving population and the associated tax base during the epidemic path." -> Across the 1,000-village Monte Carlo sample, protection changes the population die-out estimate from 99.3% to 56.0%, a change of -43.3%. Disease extinction remains very high in both scenarios (99.3% vs. 99.6%), showing why terminal disease status alone is not sufficient to evaluate the intervention. The average cumulative infection rate is 100.0% without protection and 99.4% with protection. Average cumulative tax revenue rises from $12.61M to $17.14M, an increase of about $4.53M per simulated village over the horizon. The policy value in this model therefore comes primarily from preserving population and the associated tax base during the epidemic path.
A23: Managerial / Analytical Implications
A24: • Evaluate interventions on path-dependent outcomes, not only end states: two scenarios can both end with disease extinction yet have very different mortality and economic consequences. • Pair expected outcomes with confidence intervals so decision makers can distinguish estimated effects from Monte Carlo noise. • Translate operational/health outcomes into an economic metric only with explicit units and scope; here tax is a gross preservation benefit, not a net-benefit calculation. • Scenario simulation is especially useful when nonlinear feedback matters: fewer infections today reduce the pool of infectives that can transmit disease in later periods.
I35: Scenario | J35: Tax ($000s)
I36: No Protection | J36: =B9 -> 12608.37
I37: Protection | J37: =C9 -> 17138.71

Sheet 03_Convergence
A1: Monte Carlo Convergence Check
A3: Running estimates are recomputed from progressively larger subsets of the 1,000 simulated villages. Stabilization as N grows provides a practical check that the reported scenario comparison is not driven by a small simulation sample.
A6: N | B6: Pop. die-out No Protection | C6: Pop. die-out Protection | D6: Disease die-out No Protection | E6: Disease die-out Protection | F6: Infection rate No Protection | G6: Infection rate Protection | H6: Tax ($000s) No Protection | I6: Tax ($000s) Protection | K6: N | L6: No Protection | M6: Protection
A7: 50 | B7: =AVERAGE('1Healthcare'!$AB$2:$AB$51) -> 1 | C7: =AVERAGE('1Healthcare'!$BC$2:$BC$51) -> 0.58 | D7: =AVERAGE('1Healthcare'!$AA$2:$AA$51) -> 1 | E7: =AVERAGE('1Healthcare'!$BB$2:$BB$51) -> 1 | F7: =AVERAGE('1Healthcare'!$AC$2:$AC$51) -> 1 | G7: =AVERAGE('1Healthcare'!$BD$2:$BD$51) -> 0.9934 | H7: =AVERAGE('1Healthcare'!$AD$2:$AD$51) -> 12701.4 | I7: =AVERAGE('1Healthcare'!$BE$2:$BE$51) -> 16815.8 | K7: 50 | L7: =H7 -> 12701.4 | M7: =I7 -> 16815.8
A8: 100 | B8: =AVERAGE('1Healthcare'!$AB$2:$AB$101) -> 0.99 | C8: =AVERAGE('1Healthcare'!$BC$2:$BC$101) -> 0.56 | D8: =AVERAGE('1Healthcare'!$AA$2:$AA$101) -> 0.99 | E8: =AVERAGE('1Healthcare'!$BB$2:$BB$101) -> 1 | F8: =AVERAGE('1Healthcare'!$AC$2:$AC$101) -> 1 | G8: =AVERAGE('1Healthcare'!$BD$2:$BD$101) -> 0.9935 | H8: =AVERAGE('1Healthcare'!$AD$2:$AD$101) -> 12535.4 | I8: =AVERAGE('1Healthcare'!$BE$2:$BE$101) -> 16941.7 | K8: 100 | L8: =H8 -> 12535.4 | M8: =I8 -> 16941.7
A9: 250 | B9: =AVERAGE('1Healthcare'!$AB$2:$AB$251) -> 0.988 | C9: =AVERAGE('1Healthcare'!$BC$2:$BC$251) -> 0.58 | D9: =AVERAGE('1Healthcare'!$AA$2:$AA$251) -> 0.988 | E9: =AVERAGE('1Healthcare'!$BB$2:$BB$251) -> 0.996 | F9: =AVERAGE('1Healthcare'!$AC$2:$AC$251) -> 1 | G9: =AVERAGE('1Healthcare'!$BD$2:$BD$251) -> 0.99404 | H9: =AVERAGE('1Healthcare'!$AD$2:$AD$251) -> 12580.44 | I9: =AVERAGE('1Healthcare'!$BE$2:$BE$251) -> 16920 | K9: 250 | L9: =H9 -> 12580.44 | M9: =I9 -> 16920
A10: 500 | B10: =AVERAGE('1Healthcare'!$AB$2:$AB$501) -> 0.99 | C10: =AVERAGE('1Healthcare'!$BC$2:$BC$501) -> 0.558 | D10: =AVERAGE('1Healthcare'!$AA$2:$AA$501) -> 0.99 | E10: =AVERAGE('1Healthcare'!$BB$2:$BB$501) -> 0.996 | F10: =AVERAGE('1Healthcare'!$AC$2:$AC$501) -> 1 | G10: =AVERAGE('1Healthcare'!$BD$2:$BD$501) -> 0.99368 | H10: =AVERAGE('1Healthcare'!$AD$2:$AD$501) -> 12605.1 | I10: =AVERAGE('1Healthcare'!$BE$2:$BE$501) -> 17111.42 | K10: 500 | L10: =H10 -> 12605.1 | M10: =I10 -> 17111.42
A11: 750 | B11: =AVERAGE('1Healthcare'!$AB$2:$AB$751) -> 0.992 | C11: =AVERAGE('1Healthcare'!$BC$2:$BC$751) -> 0.556 | D11: =AVERAGE('1Healthcare'!$AA$2:$AA$751) -> 0.992 | E11: =AVERAGE('1Healthcare'!$BB$2:$BB$751) -> 0.99466667 | F11: =AVERAGE('1Healthcare'!$AC$2:$AC$751) -> 1 | G11: =AVERAGE('1Healthcare'!$BD$2:$BD$751) -> 0.99361333 | H11: =AVERAGE('1Healthcare'!$AD$2:$AD$751) -> 12607.92 | I11: =AVERAGE('1Healthcare'!$BE$2:$BE$751) -> 17108.547 | K11: 750 | L11: =H11 -> 12607.92 | M11: =I11 -> 17108.547
A12: 1000 | B12: =AVERAGE('1Healthcare'!$AB$2:$AB$1001) -> 0.993 | C12: =AVERAGE('1Healthcare'!$BC$2:$BC$1001) -> 0.56 | D12: =AVERAGE('1Healthcare'!$AA$2:$AA$1001) -> 0.993 | E12: =AVERAGE('1Healthcare'!$BB$2:$BB$1001) -> 0.996 | F12: =AVERAGE('1Healthcare'!$AC$2:$AC$1001) -> 1 | G12: =AVERAGE('1Healthcare'!$BD$2:$BD$1001) -> 0.99352 | H12: =AVERAGE('1Healthcare'!$AD$2:$AD$1001) -> 12608.37 | I12: =AVERAGE('1Healthcare'!$BE$2:$BE$1001) -> 17138.71 | K12: 1000 | L12: =H12 -> 12608.37 | M12: =I12 -> 17138.71
A32: Interpretation: estimates should become progressively less sensitive to additional replications as N approaches 1,000. Probability estimates near 0 or 1 may appear stable relatively quickly, while a continuous monetary outcome such as cumulative tax can show more visible sample-to-sample variation. The final 1,000-village estimates and their confidence intervals remain the primary reported results; this sheet is a diagnostic for Monte Carlo stability, not a replacement for the full simulation.

Sheet 04_Documentation
A1: Model Documentation & Reproducibility Notes
A5: Component | B5: Specification | C5: Implementation | D5: Interpretation
A6: Population | B6: 100 residents | C6: S₁=95, I₁=5, D₁=0 | D6: Closed population; no births/migration
A7: Horizon | B7: 100 periods | C7: Dynamic sample path | D7: Outcomes evaluated at period 100
A8: Monte Carlo sample | B8: 1,000 villages | C8: Excel Data Table | D8: Independent stochastic replications
A9: Infected mortality | B9: 10% per period | C9: Binomial survival with p=0.90 | D9: No recovery state
A10: Encounter probability | B10: 5% | C10: Fixed in both scenarios | D10: Protection does not change encounters
A11: Conditional infection | B11: 50% → 10% | C11: Scenario-specific parameter | D11: Protection reduces transmission conditional on encounter
A12: Susceptible transition | B12: Binomial | C12: BINOM.INV + RAND() | D12: q_t depends on current I_t
A13: Disease die-out | B13: I₁₀₀=0 | C13: Indicator averaged across villages | D13: Terminal disease status
A14: Population die-out | B14: D₁₀₀=100 | C14: Indicator averaged across villages | D14: Catastrophic population outcome
A15: Cumulative infection | B15: (I₁₀₀+D₁₀₀)/100 | C15: Average across villages | D15: Share ever infected by horizon
A18: Economic metric | B18: Specification | C18: Unit | D18: Caution
... A22: Uncertainty | B22: 95% CI = mean ± 1.96×SE | C22: Outcome-specific units | D22: Quantifies Monte Carlo sampling uncertainty
A25: Workbook Map
A26: Sheet | B26: Purpose | C26: Notes
A27: 00_Project_Overview | B27: Problem, model, design, implications, limitations | C27: Portfolio entry point
A28: 1Healthcare | B28: Original stochastic simulation engine | C28: Original formulas and computational logic preserved
A29: 02_Results_Dashboard | B29: Scenario results and interpretation | C29: Linked to simulation outputs
A30: 03_Convergence | B30: Running-estimate stability diagnostics | C30: Linked to Monte Carlo sample
