Workbook

Sheet Meter1 TOU Detail
A1: Meter 1 TOU Detail Historical Load & TOU Detail
A2: Service account 8001881589 | Tariff TOU-GS-2-E | Meter 1
A4: Billing Period | B4: Start Date | C4: End Date | D4: Days | E4: Total Load (kWh) | F4: Bill Total ($) | G4: Summer On-Peak kWh | H4: Summer On-Peak Energy $ | I4: Summer Mid-Peak kWh | J4: Summer Mid-Peak Energy $ | K4: Summer Off-Peak kWh | L4: Summer Off-Peak Energy $ | M4: Winter Mid-Peak kWh | N4: Winter Mid-Peak Energy $ | O4: Winter Off-Peak kWh | P4: Winter Off-Peak Energy $ | Q4: Winter Super-Off-Peak kWh | R4: Winter Super-Off-Peak Energy $ | S4: Max Demand (kW) | T4: Base Demand Charge ($) | U4: Summer On-Peak Demand (kW) | V4: Summer On-Peak Demand $ | W4: Winter Mid-Peak Demand (kW) | X4: Winter Mid-Peak Demand $ | Y4: TOU Energy Charges ($) | Z4: Demand Charges ($) | AA4: Other / Residual Charges ($) | AB4: Source | AC4: Data Quality
A5: Oct 2023 | B5: 09/20/2023 | C5: 10/19/2023 | D5: 29 | E5: 7569 | F5: 2199.45 | G5: 358 | H5: 306.92 | I5: 109 | J5: 36.16 | K5: 2265 | L5: 459.02 | M5: 722 | N5: 153.91 | O5: 1767 | P5: 248.3 | Q5: 2348 | R5: 110.59 | S5: 32 | T5: 506.81 | U5: 20 | V5: 60.84 | W5: 24 | X5: 46.33 | Y5: =SUM(H5,J5,L5,N5,P5,R5) -> 1314.9 | Z5: =SUM(T5,V5,X5) -> 613.98 | AA5: =F5-Y5-Z5 -> 270.57 | AB5: https://utilityapi.com/api/v2/files/pdf_bill/1689169/8001881589_2023-09-20_to_2023-10-19.pdf | AC5: Complete
A6: Nov 2023 | B6: 10/19/2023 | C6: 11/20/2023 | D6: 32 | E6: 9408 | F6: 2092.71 | M6: 1361 | N6: 290.11 | O6: 3998 | P6: 561.8 | Q6: 4049 | R6: 190.71 | S6: 39 | T6: 562.14 | W6: 24 | X6: 74.64 | Y6: =SUM(H6,J6,L6,N6,P6,R6) -> 1042.62 | Z6: =SUM(T6,V6,X6) -> 636.78 | AA6: =F6-Y6-Z6 -> 413.31 | AB6: https://utilityapi.com/api/v2/files/pdf_bill/1689169/8001881589_2023-10-19_to_2023-11-20.pdf | AC6: Complete
A7: Dec 2023 | B7: 11/20/2023 | C7: 12/20/2023 | D7: 30 | E7: 11409 | F7: 2449.71 | M7: 1694 | N7: 361.09 | O7: 5123 | P7: 719.89 | Q7: 4592 | R7: 216.28 | S7: 43 | T7: 618.36 | W7: 26 | X7: 80.86 | Y7: =SUM(H7,J7,L7,N7,P7,R7) -> 1297.26 | Z7: =SUM(T7,V7,X7) -> 699.22 | AA7: =F7-Y7-Z7 -> 453.23 | AB7: https://utilityapi.com/api/v2/files/pdf_bill/1689169/8001881589_2023-11-20_to_2023-12-20.pdf | AC7: Complete
A8: Jan 2024 | B8: 12/20/2023 | C8: 01/22/2024 | D8: 33 | E8: 12241 | F8: 2575.94 | M8: 1904 | N8: 396.21 | O8: 5368 | P8: 736.98 | Q8: 4969 | R8: 257.42 | S8: 44 | T8: 628.02 | W8: 24 | X8: 69.9 | Y8: =SUM(H8,J8,L8,N8,P8,R8) -> 1390.61 | Z8: =SUM(T8,V8,X8) -> 697.92 | AA8: =F8-Y8-Z8 -> 487.41 | AB8: https://utilityapi.com/api/v2/files/pdf_bill/1689169/8001881589_2023-12-20_to_2024-01-22.pdf | AC8: Complete
A9: Feb 2024 | B9: 01/22/2024 | C9: 02/21/2024 | D9: 30 | E9: 10734 | F9: 2376.93 | M9: 1517 | N9: 311.44 | O9: 4591 | P9: 622.45 | Q9: 4626 | R9: 251.28 | S9: 46 | T9: 663.94 | W9: 27 | X9: 75.6 | Y9: =SUM(H9,J9,L9,N9,P9,R9) -> 1185.17 | Z9: =SUM(T9,V9,X9) -> 739.54 | AA9: =F9-Y9-Z9 -> 452.22 | AB9: https://utilityapi.com/api/v2/files/pdf_bill/1689169/8001881589_2024-01-22_to_2024-02-21.pdf | AC9: Complete
A10: Mar 2024 | B10: 02/21/2024 | C10: 03/21/2024 | D10: 29 | E10: 7646 | F10: 1802.68 | M10: 1052 | N10: 216.76 | O10: 3377 | P10: 459.26 | Q10: 3217 | R10: 176.58 | S10: 36 | T10: 510.71 | W10: 16 | X10: 44.8 | Y10: =SUM(H10,J10,L10,N10,P10,R10) -> 852.6 | Z10: =SUM(T10,V10,X10) -> 555.51 | AA10: =F10-Y10-Z10 -> 394.57 | AB10: https://utilityapi.com/api/v2/files/pdf_bill/1689169/8001881589_2024-02-21_to_2024-03-21.pdf | AC10: Complete
A11: Apr 2024 | B11: 03/21/2024 | C11: 04/22/2024 | D11: 32 | E11: 6348 | F11: 1532.43 | M11: 902 | N11: 186.19 | O11: 2653 | P11: 361.36 | Q11: 2793 | R11: 154.01 | S11: 28 | T11: 420.28 | W11: 20 | X11: 56 | Y11: =SUM(H11,J11,L11,N11,P11,R11) -> 701.56 | Z11: =SUM(T11,V11,X11) -> 476.28 | AA11: =F11-Y11-Z11 -> 354.59 | AB11: https://utilityapi.com/api/v2/files/pdf_bill/1689169/8001881589_2024-03-21_to_2024-04-22.pdf | AC11: Complete | AD11: May TOU scale factor
A12: May 2024 | B12: 04/22/2024 | C12: 05/21/2024 | D12: 29 | E12: 6057 | F12: 1515.83 | G12: =G13*$AD$12 -> 403.83324 | H12: =H13*$AD$12 -> 343.21338 | I12: =I13*$AD$12 -> 128.62836 | J12: =J13*$AD$12 -> 45.159524 | K12: =K13*$AD$12 -> 2359.6824 | L12: =L13*$AD$12 -> 502.80229 | M12: =M11*$AD$12 -> 449.70072 | N12: =N11*$AD$12 -> 92.826803 | O12: =O11*$AD$12 -> 1322.6785 | P12: =P11*$AD$12 -> 180.15948 | Q12: =Q11*$AD$12 -> 1392.4768 | R12: =R11*$AD$12 -> 76.783157 | S12: =AVERAGE(S11,S13) -> 34.5 | T12: =AVERAGE(T11,T13) -> 553.21 | U12: =U13 -> 29 | V12: =V13 -> 123.97 | W12: =W11 -> 20 | X12: =X11 -> 56 | Y12: =SUM(H12,J12,L12,N12,P12,R12) -> 1240.9446 | Z12: =SUM(T12,V12,X12) -> 733.18 | AA12: =F12-Y12-Z12 -> -458.29464 | AC12: Estimated May TOU: Jun summer components + Apr winter components | AD12: =E12/SUM(G13,I13,K13,M11,O11,Q11) -> 0.49855955
A13: Jun 2024 | B13: 05/21/2024 | C13: 06/20/2024 | D13: 30 | E13: 8802 | F13: 3167.93 | G13: 810 | H13: 688.41 | I13: 258 | J13: 90.58 | K13: 4733 | L13: 1008.51 | M13: 555 | N13: 114.56 | O13: 1023 | P13: 139.34 | Q13: 1423 | R13: 78.46 | S13: 41 | T13: 686.14 | U13: 29 | V13: 123.97 | W13: 26 | X13: 26.69 | Y13: =SUM(H13,J13,L13,N13,P13,R13) -> 2119.86 | Z13: =SUM(T13,V13,X13) -> 836.8 | AA13: =F13-Y13-Z13 -> 211.27 | AB13: https://utilityapi.com/api/v2/files/pdf_bill/1689169/8001881589_2024-05-21_to_2024-06-20.pdf | AC13: Complete
A14: Jul 2024 | B14: 06/20/2024 | C14: 07/23/2024 | D14: 33 | E14: 12723 | F14: 4972.77 | G14: 1450 | H14: 1232.34 | I14: 531 | J14: 186.42 | K14: 10742 | L14: 2288.91 | S14: 51 | T14: 944.34 | U14: 41 | V14: 276.75 | Y14: =SUM(H14,J14,L14,N14,P14,R14) -> 3707.67 | Z14: =SUM(T14,V14,X14) -> 1221.09 | AA14: =F14-Y14-Z14 -> 44.01 | AB14: https://utilityapi.com/api/v2/files/pdf_bill/1689169/8001881589_2024-06-20_to_2024-07-23.pdf | AC14: Complete
A15: Aug 2024 | B15: 07/23/2024 | C15: 08/21/2024 | D15: 29 | E15: 13067 | F15: 5128.28 | G15: 1607 | H15: 1365.77 | I15: 479 | J15: 168.17 | K15: 10981 | L15: 2339.83 | S15: 50 | T15: 931.25 | U15: 41 | V15: 276.75 | Y15: =SUM(H15,J15,L15,N15,P15,R15) -> 3873.77 | Z15: =SUM(T15,V15,X15) -> 1208 | AA15: =F15-Y15-Z15 -> 46.51 | AB15: https://utilityapi.com/api/v2/files/pdf_bill/1689169/8001881589_2024-07-23_to_2024-08-21.pdf | AC15: Complete
A16: Sep 2024 | B16: 08/21/2024 | C16: 09/20/2024 | D16: 30 | E16: 11054 | F16: 4280.39 | G16: 1177 | H16: 1000.32 | I16: 454 | J16: 159.39 | K16: 9423 | L16: 2007.85 | S16: 47 | T16: 804.23 | U16: 28 | V16: 189 | Y16: =SUM(H16,J16,L16,N16,P16,R16) -> 3167.56 | Z16: =SUM(T16,V16,X16) -> 993.23 | AA16: =F16-Y16-Z16 -> 119.6 | AB16: https://utilityapi.com/api/v2/files/pdf_bill/1689169/8001881589_2024-08-21_to_2024-09-20.pdf | AC16: Complete
A17: 12-Period Total | E17: =SUM(E5:E16) -> 117058 | F17: =SUM(F5:F16) -> 34095.05 | G17: =SUM(G5:G16) -> 5805.8332 | H17: =SUM(H5:H16) -> 4936.9734 | I17: =SUM(I5:I16) -> 1959.6284 | J17: =SUM(J5:J16) -> 685.87952 | K17: =SUM(K5:K16) -> 40503.682 | L17: =SUM(L5:L16) -> 8606.9223 | ... R17: =SUM(R5:R16) -> 1512.1132 | Y17: =SUM(Y5:Y16) -> 21894.525 | Z17: =SUM(Z5:Z16) -> 9411.53 | AA17: =SUM(AA5:AA16) -> 2788.9954

Sheet Meter2 TOU Detail
A1: Meter 2 TOU Detail Historical Load & TOU Detail
A2: Service account 8013693720 | Tariff TOU-8-D | Meter 2
A4: Billing Period | B4: Start Date | C4: End Date | D4: Days | E4: Total Load (kWh) | F4: Bill Total ($) | G4: Summer On-Peak kWh | H4: Summer On-Peak Energy $ | I4: Summer Mid-Peak kWh | J4: Summer Mid-Peak Energy $ | K4: Summer Off-Peak kWh | L4: Summer Off-Peak Energy $ | M4: Winter Mid-Peak kWh | N4: Winter Mid-Peak Energy $ | O4: Winter Off-Peak kWh | P4: Winter Off-Peak Energy $ | Q4: Winter Super-Off-Peak kWh | R4: Winter Super-Off-Peak Energy $ | S4: Max Demand (kW) | T4: Base Demand Charge ($) | U4: Summer On-Peak Demand (kW) | V4: Summer On-Peak Demand $ | W4: Winter Mid-Peak Demand (kW) | X4: Winter Mid-Peak Demand $ | Y4: TOU Energy Charges ($) | Z4: Demand Charges ($) | AA4: Other / Residual Charges ($) | AB4: Source | AC4: Data Quality
A5: Oct 2023 | B5: 09/20/2023 | C5: 10/19/2023 | D5: 29 | E5: 42448 | F5: 18373.78 | G5: 86 | H5: 14.95 | I5: 37 | J5: 5.93 | K5: 16852 | L5: 2002.19 | M5: 389 | N5: 51.56 | O5: 2382 | P5: 314.49 | Q5: 22702 | R5: 690.37 | S5: 552 | T5: 12811.13 | U5: 12 | V5: 115.89 | W5: 142 | X5: 689.24 | Y5: =SUM(H5,J5,L5,N5,P5,R5) -> 3079.49 | Z5: =SUM(T5,V5,X5) -> 13616.26 | AA5: =F5-Y5-Z5 -> 1678.03 | AB5: https://utilityapi.com/api/v2/files/pdf_bill/1689171/8013693720_2023-09-20_to_2023-10-19.pdf | AC5: Complete
A6: Nov 2023 | B6: 10/19/2023 | C6: 11/20/2023 | D6: 32 | E6: 51688 | F6: 19755.43 | M6: 293 | N6: 38.83 | O6: 3945 | P6: 520.86 | Q6: 47450 | R6: 1442.95 | S6: 622 | T6: 14032.88 | W6: 47 | X6: 367.54 | Y6: =SUM(H6,J6,L6,N6,P6,R6) -> 2002.64 | Z6: =SUM(T6,V6,X6) -> 14400.42 | AA6: =F6-Y6-Z6 -> 3352.37 | AB6: https://utilityapi.com/api/v2/files/pdf_bill/1689171/8013693720_2023-10-19_to_2023-11-20.pdf | AC6: Complete
A7: Dec 2023 | B7: 11/20/2023 | C7: 12/20/2023 | D7: 30 | E7: 41843 | F7: 17151.12 | M7: 330 | N7: 43.74 | O7: 3938 | P7: 519.93 | Q7: 37575 | R7: 1142.66 | S7: 513 | T7: 12169.91 | W7: 115 | X7: 899.3 | Y7: =SUM(H7,J7,L7,N7,P7,R7) -> 1706.33 | Z7: =SUM(T7,V7,X7) -> 13069.21 | AA7: =F7-Y7-Z7 -> 2375.58 | AB7: https://utilityapi.com/api/v2/files/pdf_bill/1689171/8013693720_2023-11-20_to_2023-12-20.pdf | AC7: Complete
A8: Jan 2024 | B8: 12/20/2023 | C8: 01/22/2024 | D8: 33 | E8: 42603 | F8: 20168.76 | M8: 233 | N8: 30.29 | O8: 3868 | P8: 499.88 | Q8: 38502 | R8: 1308.51 | S8: 655 | T8: 15251.57 | W8: 43 | X8: 315.19 | Y8: =SUM(H8,J8,L8,N8,P8,R8) -> 1838.68 | Z8: =SUM(T8,V8,X8) -> 15566.76 | AA8: =F8-Y8-Z8 -> 2763.32 | AB8: https://utilityapi.com/api/v2/files/pdf_bill/1689171/8013693720_2023-12-20_to_2024-01-22.pdf | AC8: Complete
A9: Feb 2024 | B9: 01/22/2024 | C9: 02/21/2024 | D9: 30 | E9: 38192 | F9: 19764.91 | M9: 285 | N9: 36.69 | O9: 3399 | P9: 435.04 | Q9: 34508 | R9: 1249.19 | S9: 640 | T9: 15223.5 | W9: 46 | X9: 324.3 | Y9: =SUM(H9,J9,L9,N9,P9,R9) -> 1720.92 | Z9: =SUM(T9,V9,X9) -> 15547.8 | AA9: =F9-Y9-Z9 -> 2496.19 | AB9: https://utilityapi.com/api/v2/files/pdf_bill/1689171/8013693720_2024-01-22_to_2024-02-21.pdf | AC9: Complete
A10: Mar 2024 | B10: 02/21/2024 | C10: 03/21/2024 | D10: 29 | E10: 44803 | F10: 18580.72 | M10: 385 | N10: 49.77 | O10: 4449 | P10: 571.18 | Q10: 39969 | R10: 1460 | S10: 500 | T10: 12987.94 | W10: 170 | X10: 1199.67 | Y10: =SUM(H10,J10,L10,N10,P10,R10) -> 2080.95 | Z10: =SUM(T10,V10,X10) -> 14187.61 | AA10: =F10-Y10-Z10 -> 2312.16 | AB10: https://utilityapi.com/api/v2/files/pdf_bill/1689171/8013693720_2024-02-21_to_2024-03-21.pdf | AC10: Complete
A11: Apr 2024 | B11: 03/21/2024 | C11: 04/22/2024 | D11: 32 | E11: 34404 | F11: 15527.63 | M11: 415 | N11: 53.69 | O11: 3441 | P11: 442.48 | Q11: 30548 | R11: 1119.89 | S11: 442 | T11: 11164.64 | W11: 97 | X11: 684.82 | Y11: =SUM(H11,J11,L11,N11,P11,R11) -> 1616.06 | Z11: =SUM(T11,V11,X11) -> 11849.46 | AA11: =F11-Y11-Z11 -> 2062.11 | AB11: https://utilityapi.com/api/v2/files/pdf_bill/1689171/8013693720_2024-03-21_to_2024-04-22.pdf | AC11: Complete
A12: May 2024 | B12: 04/22/2024 | C12: 05/21/2024 | D12: 29 | E12: 45163 | F12: 16968.39 | M12: 298 | N12: 38.56 | O12: 4070 | P12: 523.36 | Q12: 40795 | R12: 1495.54 | S12: 466 | T12: 11641.9 | W12: 84 | X12: 593.04 | Y12: =SUM(H12,J12,L12,N12,P12,R12) -> 2057.46 | Z12: =SUM(T12,V12,X12) -> 12234.94 | AA12: =F12-Y12-Z12 -> 2675.99 | AB12: https://utilityapi.com/api/v2/files/pdf_bill/1689171/8013693720_2024-04-22_to_2024-05-21.pdf | AC12: Complete
A13: Jun 2024 | B13: 05/21/2024 | C13: 06/20/2024 | D13: 30 | E13: 41942 | F13: 17606.49 | G13: 198 | H13: 31.61 | I13: 58 | J13: 8.57 | K13: 24786 | L13: 2792.89 | M13: 122 | N13: 15.78 | O13: 1568 | P13: 201.63 | Q13: 15210 | R13: 557.6 | S13: 471 | T13: 11775.4 | U13: 36 | V13: 490.2 | W13: 19 | X13: 49.18 | Y13: =SUM(H13,J13,L13,N13,P13,R13) -> 3608.08 | Z13: =SUM(T13,V13,X13) -> 12314.78 | AA13: =F13-Y13-Z13 -> 1683.63 | AB13: https://utilityapi.com/api/v2/files/pdf_bill/1689171/8013693720_2024-05-21_to_2024-06-20.pdf | AC13: Complete
A14: Jul 2024 | B14: 06/20/2024 | C14: 07/23/2024 | D14: 33 | E14: 68386 | F14: 28541.31 | G14: 625 | H14: 99.79 | I14: 192 | J14: 28.39 | K14: 67569 | L14: 7613.67 | S14: 725 | T14: 18496 | U14: 53 | V14: 1139.5 | Y14: =SUM(H14,J14,L14,N14,P14,R14) -> 7741.85 | Z14: =SUM(T14,V14,X14) -> 19635.5 | AA14: =F14-Y14-Z14 -> 1163.96 | AB14: https://utilityapi.com/api/v2/files/pdf_bill/1689171/8013693720_2024-06-20_to_2024-07-23.pdf | AC14: Complete
A15: Aug 2024 | B15: 07/23/2024 | C15: 08/21/2024 | D15: 29 | E15: 67656 | F15: 29001.91 | G15: 3285 | H15: 524.48 | I15: 152 | J15: 22.47 | K15: 64219 | L15: 7236.2 | S15: 705 | T15: 18490.2 | U15: 75 | V15: 1612.5 | Y15: =SUM(H15,J15,L15,N15,P15,R15) -> 7783.15 | Z15: =SUM(T15,V15,X15) -> 20102.7 | AA15: =F15-Y15-Z15 -> 1116.06 | AB15: https://utilityapi.com/api/v2/files/pdf_bill/1689171/8013693720_2024-07-23_to_2024-08-21.pdf | AC15: Complete
A16: Sep 2024 | B16: 08/21/2024 | C16: 09/20/2024 | D16: 30 | E16: 73315 | F16: 31196.61 | G16: 2605 | H16: 415.92 | I16: 175 | J16: 25.87 | K16: 70535 | L16: 7947.88 | S16: 730 | T16: 19583.2 | U16: 98 | V16: 2107 | Y16: =SUM(H16,J16,L16,N16,P16,R16) -> 8389.67 | Z16: =SUM(T16,V16,X16) -> 21690.2 | AA16: =F16-Y16-Z16 -> 1116.74 | AB16: https://utilityapi.com/api/v2/files/pdf_bill/1689171/8013693720_2024-08-21_to_2024-09-20.pdf | AC16: Complete
A17: 12-Period Total | E17: =SUM(E5:E16) -> 592443 | F17: =SUM(F5:F16) -> 252637.06 | G17: =SUM(G5:G16) -> 6799 | H17: =SUM(H5:H16) -> 1086.75 | I17: =SUM(I5:I16) -> 614 | J17: =SUM(J5:J16) -> 91.23 | K17: =SUM(K5:K16) -> 243961 | L17: =SUM(L5:L16) -> 27592.83 | ... R17: =SUM(R5:R16) -> 10466.71 | Y17: =SUM(Y5:Y16) -> 43625.28 | Z17: =SUM(Z5:Z16) -> 184215.64 | AA17: =SUM(AA5:AA16) -> 24796.14

Sheet Combined TOU Profile
A1: Barstow Historical Load & TOU Profile
A2: Two-account baseline: Meter 1 + Meter 2. Annual electricity consumption = 709,501 kWh.
A4: Billing Period | B4: Start Date | C4: End Date | D4: Meter 1 Load (kWh) | E4: Meter 2 Load (kWh) | F4: Combined Load (kWh) | G4: On-Peak kWh | H4: Mid-Peak kWh | I4: Off-Peak kWh | J4: Super-Off-Peak kWh | K4: Meter 1 Max Demand kW | L4: Meter 2 Max Demand kW | M4: Site Max-Demand Indicator kW | N4: Meter 1 TOU Peak Demand kW | O4: Meter 2 TOU Peak Demand kW | P4: Energy Charges ($) | Q4: Demand Charges ($) | R4: Bill Total ($) | S4: Other / Residual Charges ($) | T4: TOU kWh Reconciliation | U4: Data Quality | V4: Notes
A5: Oct 2023 | B5: 09/20/2023 | C5: 10/19/2023 | D5: 7569 | E5: 42448 | F5: =D5+E5 -> 50017 | G5: ='Meter1 TOU Detail'!G5+'Meter2 TOU Detail'!G5 -> 444 | H5: =SUM('Meter1 TOU Detail'!I5,'Meter1 TOU Detail'!M5,'Meter2 TOU Detail'!I5,'Meter2 TOU Detail'!M5) -> 1257 | I5: =SUM('Meter1 TOU Detail'!K5,'Meter1 TOU Detail'!O5,'Meter2 TOU Detail'!K5,'Meter2 TOU Detail'!O5) -> 23266 | J5: ='Meter1 TOU Detail'!Q5+'Meter2 TOU Detail'!Q5 -> 25050 | K5: ='Meter1 TOU Detail'!S5 -> 32 | L5: ='Meter2 TOU Detail'!S5 -> 552 | M5: =MAX(K5:L5) -> 552 | N5: =MAX('Meter1 TOU Detail'!U5,'Meter1 TOU Detail'!W5) -> 24 | O5: =MAX('Meter2 TOU Detail'!U5,'Meter2 TOU Detail'!W5) -> 142 | P5: ='Meter1 TOU Detail'!Y5+'Meter2 TOU Detail'!Y5 -> 4394.39 | Q5: ='Meter1 TOU Detail'!Z5+'Meter2 TOU Detail'!Z5 -> 14230.24 | R5: ='Meter1 TOU Detail'!F5+'Meter2 TOU Detail'!F5 -> 20573.23 | S5: =R5-P5-Q5 -> 1948.6 | T5: =SUM(G5:J5)-F5 -> 0 | U5: Complete | V5: Site max-demand indicator is MAX(account peaks), not a coincident summed site peak.
A6: Nov 2023 | B6: 10/19/2023 | C6: 11/20/2023 | D6: 9408 | E6: 51688 | F6: =D6+E6 -> 61096 | G6: ='Meter1 TOU Detail'!G6+'Meter2 TOU Detail'!G6 -> 0 | H6: =SUM('Meter1 TOU Detail'!I6,'Meter1 TOU Detail'!M6,'Meter2 TOU Detail'!I6,'Meter2 TOU Detail'!M6) -> 1654 | I6: =SUM('Meter1 TOU Detail'!K6,'Meter1 TOU Detail'!O6,'Meter2 TOU Detail'!K6,'Meter2 TOU Detail'!O6) -> 7943 | J6: ='Meter1 TOU Detail'!Q6+'Meter2 TOU Detail'!Q6 -> 51499 | K6: ='Meter1 TOU Detail'!S6 -> 39 | L6: ='Meter2 TOU Detail'!S6 -> 622 | M6: =MAX(K6:L6) -> 622 | N6: =MAX('Meter1 TOU Detail'!U6,'Meter1 TOU Detail'!W6) -> 24 | O6: =MAX('Meter2 TOU Detail'!U6,'Meter2 TOU Detail'!W6) -> 47 | P6: ='Meter1 TOU Detail'!Y6+'Meter2 TOU Detail'!Y6 -> 3045.26 | Q6: ='Meter1 TOU Detail'!Z6+'Meter2 TOU Detail'!Z6 -> 15037.2 | R6: ='Meter1 TOU Detail'!F6+'Meter2 TOU Detail'!F6 -> 21848.14 | S6: =R6-P6-Q6 -> 3765.68 | T6: =SUM(G6:J6)-F6 -> 0 | U6: Complete | V6: Site max-demand indicator is MAX(account peaks), not a coincident summed site peak.
A7: Dec 2023 | B7: 11/20/2023 | C7: 12/20/2023 | D7: 11409 | E7: 41843 | F7: =D7+E7 -> 53252 | G7: ='Meter1 TOU Detail'!G7+'Meter2 TOU Detail'!G7 -> 0 | H7: =SUM('Meter1 TOU Detail'!I7,'Meter1 TOU Detail'!M7,'Meter2 TOU Detail'!I7,'Meter2 TOU Detail'!M7) -> 2024 | I7: =SUM('Meter1 TOU Detail'!K7,'Meter1 TOU Detail'!O7,'Meter2 TOU Detail'!K7,'Meter2 TOU Detail'!O7) -> 9061 | J7: ='Meter1 TOU Detail'!Q7+'Meter2 TOU Detail'!Q7 -> 42167 | K7: ='Meter1 TOU Detail'!S7 -> 43 | L7: ='Meter2 TOU Detail'!S7 -> 513 | M7: =MAX(K7:L7) -> 513 | N7: =MAX('Meter1 TOU Detail'!U7,'Meter1 TOU Detail'!W7) -> 26 | O7: =MAX('Meter2 TOU Detail'!U7,'Meter2 TOU Detail'!W7) -> 115 | P7: ='Meter1 TOU Detail'!Y7+'Meter2 TOU Detail'!Y7 -> 3003.59 | Q7: ='Meter1 TOU Detail'!Z7+'Meter2 TOU Detail'!Z7 -> 13768.43 | R7: ='Meter1 TOU Detail'!F7+'Meter2 TOU Detail'!F7 -> 19600.83 | S7: =R7-P7-Q7 -> 2828.81 | T7: =SUM(G7:J7)-F7 -> 0 | U7: Complete | V7: Site max-demand indicator is MAX(account peaks), not a coincident summed site peak.
A8: Jan 2024 | B8: 12/20/2023 | C8: 01/22/2024 | D8: 12241 | E8: 42603 | F8: =D8+E8 -> 54844 | G8: ='Meter1 TOU Detail'!G8+'Meter2 TOU Detail'!G8 -> 0 | H8: =SUM('Meter1 TOU Detail'!I8,'Meter1 TOU Detail'!M8,'Meter2 TOU Detail'!I8,'Meter2 TOU Detail'!M8) -> 2137 | I8: =SUM('Meter1 TOU Detail'!K8,'Meter1 TOU Detail'!O8,'Meter2 TOU Detail'!K8,'Meter2 TOU Detail'!O8) -> 9236 | J8: ='Meter1 TOU Detail'!Q8+'Meter2 TOU Detail'!Q8 -> 43471 | K8: ='Meter1 TOU Detail'!S8 -> 44 | L8: ='Meter2 TOU Detail'!S8 -> 655 | M8: =MAX(K8:L8) -> 655 | N8: =MAX('Meter1 TOU Detail'!U8,'Meter1 TOU Detail'!W8) -> 24 | O8: =MAX('Meter2 TOU Detail'!U8,'Meter2 TOU Detail'!W8) -> 43 | P8: ='Meter1 TOU Detail'!Y8+'Meter2 TOU Detail'!Y8 -> 3229.29 | Q8: ='Meter1 TOU Detail'!Z8+'Meter2 TOU Detail'!Z8 -> 16264.68 | R8: ='Meter1 TOU Detail'!F8+'Meter2 TOU Detail'!F8 -> 22744.7 | S8: =R8-P8-Q8 -> 3250.73 | T8: =SUM(G8:J8)-F8 -> 0 | U8: Complete | V8: Site max-demand indicator is MAX(account peaks), not a coincident summed site peak.
A9: Feb 2024 | B9: 01/22/2024 | C9: 02/21/2024 | D9: 10734 | E9: 38192 | F9: =D9+E9 -> 48926 | G9: ='Meter1 TOU Detail'!G9+'Meter2 TOU Detail'!G9 -> 0 | H9: =SUM('Meter1 TOU Detail'!I9,'Meter1 TOU Detail'!M9,'Meter2 TOU Detail'!I9,'Meter2 TOU Detail'!M9) -> 1802 | I9: =SUM('Meter1 TOU Detail'!K9,'Meter1 TOU Detail'!O9,'Meter2 TOU Detail'!K9,'Meter2 TOU Detail'!O9) -> 7990 | J9: ='Meter1 TOU Detail'!Q9+'Meter2 TOU Detail'!Q9 -> 39134 | K9: ='Meter1 TOU Detail'!S9 -> 46 | L9: ='Meter2 TOU Detail'!S9 -> 640 | M9: =MAX(K9:L9) -> 640 | N9: =MAX('Meter1 TOU Detail'!U9,'Meter1 TOU Detail'!W9) -> 27 | O9: =MAX('Meter2 TOU Detail'!U9,'Meter2 TOU Detail'!W9) -> 46 | P9: ='Meter1 TOU Detail'!Y9+'Meter2 TOU Detail'!Y9 -> 2906.09 | Q9: ='Meter1 TOU Detail'!Z9+'Meter2 TOU Detail'!Z9 -> 16287.34 | R9: ='Meter1 TOU Detail'!F9+'Meter2 TOU Detail'!F9 -> 22141.84 | S9: =R9-P9-Q9 -> 2948.41 | T9: =SUM(G9:J9)-F9 -> 0 | U9: Complete | V9: Site max-demand indicator is MAX(account peaks), not a coincident summed site peak.
A10: Mar 2024 | B10: 02/21/2024 | C10: 03/21/2024 | D10: 7646 | E10: 44803 | F10: =D10+E10 -> 52449 | G10: ='Meter1 TOU Detail'!G10+'Meter2 TOU Detail'!G10 -> 0 | H10: =SUM('Meter1 TOU Detail'!I10,'Meter1 TOU Detail'!M10,'Meter2 TOU Detail'!I10,'Meter2 TOU Detail'!M10) -> 1437 | I10: =SUM('Meter1 TOU Detail'!K10,'Meter1 TOU Detail'!O10,'Meter2 TOU Detail'!K10,'Meter2 TOU Detail'!O10) -> 7826 | J10: ='Meter1 TOU Detail'!Q10+'Meter2 TOU Detail'!Q10 -> 43186 | K10: ='Meter1 TOU Detail'!S10 -> 36 | L10: ='Meter2 TOU Detail'!S10 -> 500 | M10: =MAX(K10:L10) -> 500 | N10: =MAX('Meter1 TOU Detail'!U10,'Meter1 TOU Detail'!W10) -> 16 | O10: =MAX('Meter2 TOU Detail'!U10,'Meter2 TOU Detail'!W10) -> 170 | P10: ='Meter1 TOU Detail'!Y10+'Meter2 TOU Detail'!Y10 -> 2933.55 | Q10: ='Meter1 TOU Detail'!Z10+'Meter2 TOU Detail'!Z10 -> 14743.12 | R10: ='Meter1 TOU Detail'!F10+'Meter2 TOU Detail'!F10 -> 20383.4 | S10: =R10-P10-Q10 -> 2706.73 | T10: =SUM(G10:J10)-F10 -> 0 | U10: Complete | V10: Site max-demand indicator is MAX(account peaks), not a coincident summed site peak.
A11: Apr 2024 | B11: 03/21/2024 | C11: 04/22/2024 | D11: 6348 | E11: 34404 | F11: =D11+E11 -> 40752 | G11: ='Meter1 TOU Detail'!G11+'Meter2 TOU Detail'!G11 -> 0 | H11: =SUM('Meter1 TOU Detail'!I11,'Meter1 TOU Detail'!M11,'Meter2 TOU Detail'!I11,'Meter2 TOU Detail'!M11) -> 1317 | I11: =SUM('Meter1 TOU Detail'!K11,'Meter1 TOU Detail'!O11,'Meter2 TOU Detail'!K11,'Meter2 TOU Detail'!O11) -> 6094 | J11: ='Meter1 TOU Detail'!Q11+'Meter2 TOU Detail'!Q11 -> 33341 | K11: ='Meter1 TOU Detail'!S11 -> 28 | L11: ='Meter2 TOU Detail'!S11 -> 442 | M11: =MAX(K11:L11) -> 442 | N11: =MAX('Meter1 TOU Detail'!U11,'Meter1 TOU Detail'!W11) -> 20 | O11: =MAX('Meter2 TOU Detail'!U11,'Meter2 TOU Detail'!W11) -> 97 | P11: ='Meter1 TOU Detail'!Y11+'Meter2 TOU Detail'!Y11 -> 2317.62 | Q11: ='Meter1 TOU Detail'!Z11+'Meter2 TOU Detail'!Z11 -> 12325.74 | R11: ='Meter1 TOU Detail'!F11+'Meter2 TOU Detail'!F11 -> 17060.06 | S11: =R11-P11-Q11 -> 2416.7 | T11: =SUM(G11:J11)-F11 -> 0 | U11: Complete | V11: Site max-demand indicator is MAX(account peaks), not a coincident summed site peak.
A12: May 2024 | B12: 04/22/2024 | C12: 05/21/2024 | D12: 6057 | E12: 45163 | F12: =D12+E12 -> 51220 | G12: ='Meter1 TOU Detail'!G12+'Meter2 TOU Detail'!G12 -> 403.83324 | H12: =SUM('Meter1 TOU Detail'!I12,'Meter1 TOU Detail'!M12,'Meter2 TOU Detail'!I12,'Meter2 TOU Detail'!M12) -> 876.32908 | I12: =SUM('Meter1 TOU Detail'!K12,'Meter1 TOU Detail'!O12,'Meter2 TOU Detail'!K12,'Meter2 TOU Detail'!O12) -> 7752.3609 | J12: ='Meter1 TOU Detail'!Q12+'Meter2 TOU Detail'!Q12 -> 42187.477 | K12: ='Meter1 TOU Detail'!S12 -> 34.5 | L12: ='Meter2 TOU Detail'!S12 -> 466 | M12: =MAX(K12:L12) -> 466 | N12: =MAX('Meter1 TOU Detail'!U12,'Meter1 TOU Detail'!W12) -> 29 | O12: =MAX('Meter2 TOU Detail'!U12,'Meter2 TOU Detail'!W12) -> 84 | P12: ='Meter1 TOU Detail'!Y12+'Meter2 TOU Detail'!Y12 -> 3298.4046 | Q12: ='Meter1 TOU Detail'!Z12+'Meter2 TOU Detail'!Z12 -> 12968.12 | R12: ='Meter1 TOU Detail'!F12+'Meter2 TOU Detail'!F12 -> 18484.22 | S12: =R12-P12-Q12 -> 2217.6954 | T12: =SUM(G12:J12)-F12 -> 0 | U12: Estimated — Meter1 May TOU from adjacent periods | V12: Meter 1 May TOU estimated using adjacent Apr/Jun periods and scaled to known 6,057-kWh total; 2957 remains actual source data. Site max-demand indicator is MAX(account peaks), not coincident summed demand.
A13: Jun 2024 | B13: 05/21/2024 | C13: 06/20/2024 | D13: 8802 | E13: 41942 | F13: =D13+E13 -> 50744 | G13: ='Meter1 TOU Detail'!G13+'Meter2 TOU Detail'!G13 -> 1008 | H13: =SUM('Meter1 TOU Detail'!I13,'Meter1 TOU Detail'!M13,'Meter2 TOU Detail'!I13,'Meter2 TOU Detail'!M13) -> 993 | I13: =SUM('Meter1 TOU Detail'!K13,'Meter1 TOU Detail'!O13,'Meter2 TOU Detail'!K13,'Meter2 TOU Detail'!O13) -> 32110 | J13: ='Meter1 TOU Detail'!Q13+'Meter2 TOU Detail'!Q13 -> 16633 | K13: ='Meter1 TOU Detail'!S13 -> 41 | L13: ='Meter2 TOU Detail'!S13 -> 471 | M13: =MAX(K13:L13) -> 471 | N13: =MAX('Meter1 TOU Detail'!U13,'Meter1 TOU Detail'!W13) -> 29 | O13: =MAX('Meter2 TOU Detail'!U13,'Meter2 TOU Detail'!W13) -> 36 | P13: ='Meter1 TOU Detail'!Y13+'Meter2 TOU Detail'!Y13 -> 5727.94 | Q13: ='Meter1 TOU Detail'!Z13+'Meter2 TOU Detail'!Z13 -> 13151.58 | R13: ='Meter1 TOU Detail'!F13+'Meter2 TOU Detail'!F13 -> 20774.42 | S13: =R13-P13-Q13 -> 1894.9 | T13: =SUM(G13:J13)-F13 -> 0 | U13: Complete | V13: Site max-demand indicator is MAX(account peaks), not a coincident summed site peak.
A14: Jul 2024 | B14: 06/20/2024 | C14: 07/23/2024 | D14: 12723 | E14: 68386 | F14: =D14+E14 -> 81109 | G14: ='Meter1 TOU Detail'!G14+'Meter2 TOU Detail'!G14 -> 2075 | H14: =SUM('Meter1 TOU Detail'!I14,'Meter1 TOU Detail'!M14,'Meter2 TOU Detail'!I14,'Meter2 TOU Detail'!M14) -> 723 | I14: =SUM('Meter1 TOU Detail'!K14,'Meter1 TOU Detail'!O14,'Meter2 TOU Detail'!K14,'Meter2 TOU Detail'!O14) -> 78311 | J14: ='Meter1 TOU Detail'!Q14+'Meter2 TOU Detail'!Q14 -> 0 | K14: ='Meter1 TOU Detail'!S14 -> 51 | L14: ='Meter2 TOU Detail'!S14 -> 725 | M14: =MAX(K14:L14) -> 725 | N14: =MAX('Meter1 TOU Detail'!U14,'Meter1 TOU Detail'!W14) -> 41 | O14: =MAX('Meter2 TOU Detail'!U14,'Meter2 TOU Detail'!W14) -> 53 | P14: ='Meter1 TOU Detail'!Y14+'Meter2 TOU Detail'!Y14 -> 11449.52 | Q14: ='Meter1 TOU Detail'!Z14+'Meter2 TOU Detail'!Z14 -> 20856.59 | R14: ='Meter1 TOU Detail'!F14+'Meter2 TOU Detail'!F14 -> 33514.08 | S14: =R14-P14-Q14 -> 1207.97 | T14: =SUM(G14:J14)-F14 -> 0 | U14: Complete | V14: Site max-demand indicator is MAX(account peaks), not a coincident summed site peak.
A15: Aug 2024 | B15: 07/23/2024 | C15: 08/21/2024 | D15: 13067 | E15: 67656 | F15: =D15+E15 -> 80723 | G15: ='Meter1 TOU Detail'!G15+'Meter2 TOU Detail'!G15 -> 4892 | H15: =SUM('Meter1 TOU Detail'!I15,'Meter1 TOU Detail'!M15,'Meter2 TOU Detail'!I15,'Meter2 TOU Detail'!M15) -> 631 | I15: =SUM('Meter1 TOU Detail'!K15,'Meter1 TOU Detail'!O15,'Meter2 TOU Detail'!K15,'Meter2 TOU Detail'!O15) -> 75200 | J15: ='Meter1 TOU Detail'!Q15+'Meter2 TOU Detail'!Q15 -> 0 | K15: ='Meter1 TOU Detail'!S15 -> 50 | L15: ='Meter2 TOU Detail'!S15 -> 705 | M15: =MAX(K15:L15) -> 705 | N15: =MAX('Meter1 TOU Detail'!U15,'Meter1 TOU Detail'!W15) -> 41 | O15: =MAX('Meter2 TOU Detail'!U15,'Meter2 TOU Detail'!W15) -> 75 | P15: ='Meter1 TOU Detail'!Y15+'Meter2 TOU Detail'!Y15 -> 11656.92 | Q15: ='Meter1 TOU Detail'!Z15+'Meter2 TOU Detail'!Z15 -> 21310.7 | R15: ='Meter1 TOU Detail'!F15+'Meter2 TOU Detail'!F15 -> 34130.19 | S15: =R15-P15-Q15 -> 1162.57 | T15: =SUM(G15:J15)-F15 -> 0 | U15: Complete | V15: Site max-demand indicator is MAX(account peaks), not a coincident summed site peak.
A16: Sep 2024 | B16: 08/21/2024 | C16: 09/20/2024 | D16: 11054 | E16: 73315 | F16: =D16+E16 -> 84369 | G16: ='Meter1 TOU Detail'!G16+'Meter2 TOU Detail'!G16 -> 3782 | H16: =SUM('Meter1 TOU Detail'!I16,'Meter1 TOU Detail'!M16,'Meter2 TOU Detail'!I16,'Meter2 TOU Detail'!M16) -> 629 | I16: =SUM('Meter1 TOU Detail'!K16,'Meter1 TOU Detail'!O16,'Meter2 TOU Detail'!K16,'Meter2 TOU Detail'!O16) -> 79958 | J16: ='Meter1 TOU Detail'!Q16+'Meter2 TOU Detail'!Q16 -> 0 | K16: ='Meter1 TOU Detail'!S16 -> 47 | L16: ='Meter2 TOU Detail'!S16 -> 730 | M16: =MAX(K16:L16) -> 730 | N16: =MAX('Meter1 TOU Detail'!U16,'Meter1 TOU Detail'!W16) -> 28 | O16: =MAX('Meter2 TOU Detail'!U16,'Meter2 TOU Detail'!W16) -> 98 | P16: ='Meter1 TOU Detail'!Y16+'Meter2 TOU Detail'!Y16 -> 11557.23 | Q16: ='Meter1 TOU Detail'!Z16+'Meter2 TOU Detail'!Z16 -> 22683.43 | R16: ='Meter1 TOU Detail'!F16+'Meter2 TOU Detail'!F16 -> 35477 | S16: =R16-P16-Q16 -> 1236.34 | T16: =SUM(G16:J16)-F16 -> 0 | U16: Complete | V16: Site max-demand indicator is MAX(account peaks), not a coincident summed site peak.
A17: 12-Period Total / Summary | D17: =SUM(D5:D16) -> 117058 | E17: =SUM(E5:E16) -> 592443 | F17: =SUM(F5:F16) -> 709501 | G17: =SUM(G5:G16) -> 12604.833 | H17: =SUM(H5:H16) -> 15480.329 | I17: =SUM(I5:I16) -> 344747.36 | J17: =SUM(J5:J16) -> 336668.48 | K17: =MAX(K5:K16) -> 51 | L17: =MAX(L5:L16) -> 730 | M17: =MAX(M5:M16) -> 730 | N17: =MAX(N5:N16) -> 41 | O17: =MAX(O5:O16) -> 170 | P17: =SUM(P5:P16) -> 65519.805 | Q17: =SUM(Q5:Q16) -> 193627.17 | R17: =SUM(R5:R16) -> 286732.11 | S17: =SUM(S5:S16) -> 27585.135 | U17: Annual load verified

Sheet Documentation
A1: Barstow Historical Load & TOU Profile — Documentation
A3: Item | B3: Definition / Method
A4: Baseline window | B4: 12 billing cycles ending Oct 2023 through Sep 2024.
A5: Verified annual electricity consumption | B5: 709,501 kWh = 117,058 kWh (Meter 1) + 592,443 kWh (Meter 2). This is electricity load, not PV generation.
A6: On-Peak kWh | B6: Summer On-Peak usage from the source utility records.
A7: Mid-Peak kWh | B7: Summer Mid-Peak + Winter Mid-Peak usage.
A8: Off-Peak kWh | B8: Summer Off-Peak + Winter Off-Peak usage.
A9: Super-Off-Peak kWh | B9: Winter Super-Off-Peak usage.
A10: TOU peak demand | B10: Summer On-Peak Demand kW in summer; Winter Mid-Peak Demand kW in winter/mixed periods.
A11: Site max-demand indicator | B11: MAX of the two account-level monthly maximum demands.
A12: Energy charges | B12: Sum of the available seasonal TOU energy-charge fields in each bill record.
A13: May 2024 estimation | B13: Meter 1 May 2024 total load (6,057 kWh) and bill total are observed. Missing TOU detail is estimated from the immediately adjacent Apr and Jun 2024 periods. Seasonal components are taken from the nearest applicable adjacent period and proportionally scaled so estimated TOU kWh reconcile exactly to the observed 6,057-kWh May total. Max demand/base demand charge use the Apr–Jun average.
A14: Residual charges | B14: Bill total minus extracted TOU energy charges minus extracted demand charges; may include customer, taxes, reactive/other charges not separately represented in the source columns.

Sheet Model Assumptions
A1: Barstow PV & ESS Sizing Model — Assumptions
A3: Category | B3: Input | C3: Value | D3: Unit | E3: Status | F3: Basis / Note
A4: Load | B4: Verified annual load | C4: 709501 | D4: kWh/year | E4: Verified | F4: 12-period historical baseline
A5: PV | B5: Panel nameplate | C5: 0.485 | D5: kW DC/panel | E5: Specified | F5: 485 W panel
A6: PV | B6: Reference PV capacity | C6: 485 | D6: kW DC | E6: Historical modeled | F6: ETB PV configuration
A7: PV | B7: Reference annual PV generation | C7: 847503 | D7: kWh/year | E7: Historical modeled | F7: ETB modeled generation
A8: PV | B8: Reference panel count | C8: 1000 | D8: panels | E8: Specified | F8: 485 kW / 0.485 kW per panel
A9: PV | B9: Minimum annual coverage | C9: 1 | D9: x | E9: Constraint | F9: Annual PV generation must be >= verified annual load
A10: ESS | B10: Battery sizing-unit energy | C10: 215.04 | D10: kWh/unit | E10: Product-source basis | F10: 215.04 kWh battery cluster sizing unit
A11: ESS | B11: Design discharge rate | C11: 0.5 | D11: C | E11: Product-source basis | F11: 0.5C listed for 215.04 kWh battery cluster
A12: ESS | B12: Implied sizing-unit power | C12: =C10*C11 -> 107.52 | D12: kW/unit | E12: Product-source basis | F12: Energy × C-rate
A13: ESS | B13: Usable energy fraction | C13: 0.9 | D13: x | E13: Modeling assumption | F13: Conservative usable-energy assumption.
A14: ESS | B14: Discharge efficiency | C14: 0.95 | D14: x | E14: Modeling assumption | F14: Assumed discharge efficiency.
A15: ESS | B15: Legacy demand-shave reference (retired from proposal calc) | C15: 0.2 | D15: x | E15: Assumption | F15: Screening target, not measured dispatch result
A16: Finance | B16: Export value | C16: 0.05 | D16: $/kWh | E16: Verified | F16: value for PV surplus
A17: Finance | B17: PV installed cost | C17: 2.01 | D17: $/W DC | E17: Historical internal value | F17: cost snapshot
A18: Finance | B18: ESS installed cost | C18: 600 | D18: $/kWh | E18: Historical internal value | F18: component-level ESS cost snapshot
A19: Finance | B19: Analysis horizon | C19: 30 | D19: years | E19: Assumption | F19: Screening financial horizon
A20: Finance | B20: Discount rate | C20: 0.05 | D20: x | E20: Historical assumption | F20: proposal financial assumption
A21: Finance | B21: Electricity escalation | C21: 0.03 | D21: x/year | E21: Historical assumption | F21: proposal financial assumption
A22: Finance | B22: PV degradation | C22: 0.008 | D22: x/year | E22: Historical assumption | F22: proposal financial assumption
B25: Proposal demand-shave target (Meter 2 account, kW) | C25: 100
B27: Federal ITC proposal-case rate | C27: 0.3 | D27: x | E27: Current policy | F27: 48E/PWA/eligibility verified
B28: Federal depreciation effective tax-benefit rate | C28: 0.255 | D28: x | E28: Current policy | F28: 30% tax rate × 85% post-ITC depreciable basis
B29: California depreciation effective tax-benefit rate | C29: 0.08 | D29: x | E29: Current policy | F29: official website verified
B30: AC PCS rating per 215.04-kWh unit | C30: 100 | D30: kW AC/unit | E30: Modeling assumption | F30: Comparable-product benchmark
B31: Total AC PCS rating — 2 units | C31: 200 | D31: kW AC | E31: Derived assumption | F31: 2 × 100 kW assumed AC PCS.

Sheet PV Production
A1: PV Panel Sizing & Monthly Production
A2: Monthly PV shape is calculated from the 485-kW panel. Candidate-system production is scaled linearly by DC capacity. Load uses billing-cycle ending month, so month-to-month comparison is a screening approximation rather than interval simulation.
A4: Month | B4: Historical Load (kWh) | C4: Reference PV Gen @485kW (kWh) | D4: Reference Yield (kWh/kW) | E4: Min Panels Candidate | F4: Candidate PV DC (kW) | G4: Candidate PV Gen (kWh) | H4: Monthly Surplus/(Deficit) (kWh) | I4: PV-to-Load | J4: Self-Consumed PV Proxy (kWh) | K4: Export/Surplus Proxy (kWh)
A5: Jan 2024 | B5: ='Combined TOU Profile'!F8 -> 54844 | C5: 51780 | D5: =C5/'Model Assumptions'!$C$6 -> 106.76289 | E5: =ROUNDUP('Model Assumptions'!$C$4/('Model Assumptions'!$C$7/'Model Assumptions'!$C$8),0) -> 838 | F5: =E5*'Model Assumptions'!$C$5 -> 406.43 | G5: =C5*F5/'Model Assumptions'!$C$6 -> 43391.64 | H5: =G5-B5 -> -11452.36 | I5: =G5/B5 -> 0.79118299 | J5: =MIN(G5,B5) -> 43391.64 | K5: =MAX(G5-B5,0) -> 0
A6: Feb 2024 | B6: ='Combined TOU Profile'!F9 -> 48926 | C6: 55888 | D6: =C6/'Model Assumptions'!$C$6 -> 115.23299 | E6: =ROUNDUP('Model Assumptions'!$C$4/('Model Assumptions'!$C$7/'Model Assumptions'!$C$8),0) -> 838 | F6: =E6*'Model Assumptions'!$C$5 -> 406.43 | G6: =C6*F6/'Model Assumptions'!$C$6 -> 46834.144 | H6: =G6-B6 -> -2091.856 | I6: =G6/B6 -> 0.95724449 | J6: =MIN(G6,B6) -> 46834.144 | K6: =MAX(G6-B6,0) -> 0
A7: Mar 2024 | B7: ='Combined TOU Profile'!F10 -> 52449 | C7: 73686 | D7: =C7/'Model Assumptions'!$C$6 -> 151.9299 | E7: =ROUNDUP('Model Assumptions'!$C$4/('Model Assumptions'!$C$7/'Model Assumptions'!$C$8),0) -> 838 | F7: =E7*'Model Assumptions'!$C$5 -> 406.43 | G7: =C7*F7/'Model Assumptions'!$C$6 -> 61748.868 | H7: =G7-B7 -> 9299.868 | I7: =G7/B7 -> 1.1773126 | J7: =MIN(G7,B7) -> 52449 | K7: =MAX(G7-B7,0) -> 9299.868
A8: Apr 2024 | B8: ='Combined TOU Profile'!F11 -> 40752 | C8: 82939 | D8: =C8/'Model Assumptions'!$C$6 -> 171.00825 | E8: =ROUNDUP('Model Assumptions'!$C$4/('Model Assumptions'!$C$7/'Model Assumptions'!$C$8),0) -> 838 | F8: =E8*'Model Assumptions'!$C$5 -> 406.43 | G8: =C8*F8/'Model Assumptions'!$C$6 -> 69502.882 | H8: =G8-B8 -> 28750.882 | I8: =G8/B8 -> 1.7055085 | J8: =MIN(G8,B8) -> 40752 | K8: =MAX(G8-B8,0) -> 28750.882
A9: May 2024 | B9: ='Combined TOU Profile'!F12 -> 51220 | C9: 91798 | D9: =C9/'Model Assumptions'!$C$6 -> 189.27423 | E9: =ROUNDUP('Model Assumptions'!$C$4/('Model Assumptions'!$C$7/'Model Assumptions'!$C$8),0) -> 838 | F9: =E9*'Model Assumptions'!$C$5 -> 406.43 | G9: =C9*F9/'Model Assumptions'!$C$6 -> 76926.724 | H9: =G9-B9 -> 25706.724 | I9: =G9/B9 -> 1.5018884 | J9: =MIN(G9,B9) -> 51220 | K9: =MAX(G9-B9,0) -> 25706.724
A10: Jun 2024 | B10: ='Combined TOU Profile'!F13 -> 50744 | C10: 91057 | D10: =C10/'Model Assumptions'!$C$6 -> 187.74639 | E10: =ROUNDUP('Model Assumptions'!$C$4/('Model Assumptions'!$C$7/'Model Assumptions'!$C$8),0) -> 838 | F10: =E10*'Model Assumptions'!$C$5 -> 406.43 | G10: =C10*F10/'Model Assumptions'!$C$6 -> 76305.766 | H10: =G10-B10 -> 25561.766 | I10: =G10/B10 -> 1.5037397 | J10: =MIN(G10,B10) -> 50744 | K10: =MAX(G10-B10,0) -> 25561.766
A11: Jul 2024 | B11: ='Combined TOU Profile'!F14 -> 81109 | C11: 84094 | D11: =C11/'Model Assumptions'!$C$6 -> 173.38969 | E11: =ROUNDUP('Model Assumptions'!$C$4/('Model Assumptions'!$C$7/'Model Assumptions'!$C$8),0) -> 838 | F11: =E11*'Model Assumptions'!$C$5 -> 406.43 | G11: =C11*F11/'Model Assumptions'!$C$6 -> 70470.772 | H11: =G11-B11 -> -10638.228 | I11: =G11/B11 -> 0.86884035 | J11: =MIN(G11,B11) -> 70470.772 | K11: =MAX(G11-B11,0) -> 0
A12: Aug 2024 | B12: ='Combined TOU Profile'!F15 -> 80723 | C12: 83095 | D12: =C12/'Model Assumptions'!$C$6 -> 171.3299 | E12: =ROUNDUP('Model Assumptions'!$C$4/('Model Assumptions'!$C$7/'Model Assumptions'!$C$8),0) -> 838 | F12: =E12*'Model Assumptions'!$C$5 -> 406.43 | G12: =C12*F12/'Model Assumptions'!$C$6 -> 69633.61 | H12: =G12-B12 -> -11089.39 | I12: =G12/B12 -> 0.86262416 | J12: =MIN(G12,B12) -> 69633.61 | K12: =MAX(G12-B12,0) -> 0
A13: Sep 2024 | B13: ='Combined TOU Profile'!F16 -> 84369 | C13: 72370 | D13: =C13/'Model Assumptions'!$C$6 -> 149.21649 | E13: =ROUNDUP('Model Assumptions'!$C$4/('Model Assumptions'!$C$7/'Model Assumptions'!$C$8),0) -> 838 | F13: =E13*'Model Assumptions'!$C$5 -> 406.43 | G13: =C13*F13/'Model Assumptions'!$C$6 -> 60646.06 | H13: =G13-B13 -> -23722.94 | I13: =G13/B13 -> 0.71881923 | J13: =MIN(G13,B13) -> 60646.06 | K13: =MAX(G13-B13,0) -> 0
A14: Oct 2023 | B14: ='Combined TOU Profile'!F5 -> 50017 | C14: 65606 | D14: =C14/'Model Assumptions'!$C$6 -> 135.2701 | E14: =ROUNDUP('Model Assumptions'!$C$4/('Model Assumptions'!$C$7/'Model Assumptions'!$C$8),0) -> 838 | F14: =E14*'Model Assumptions'!$C$5 -> 406.43 | G14: =C14*F14/'Model Assumptions'!$C$6 -> 54977.828 | H14: =G14-B14 -> 4960.828 | I14: =G14/B14 -> 1.0991828 | J14: =MIN(G14,B14) -> 50017 | K14: =MAX(G14-B14,0) -> 4960.828
A15: Nov 2023 | B15: ='Combined TOU Profile'!F6 -> 61096 | C15: 51050 | D15: =C15/'Model Assumptions'!$C$6 -> 105.25773 | E15: =ROUNDUP('Model Assumptions'!$C$4/('Model Assumptions'!$C$7/'Model Assumptions'!$C$8),0) -> 838 | F15: =E15*'Model Assumptions'!$C$5 -> 406.43 | G15: =C15*F15/'Model Assumptions'!$C$6 -> 42779.9 | H15: =G15-B15 -> -18316.1 | I15: =G15/B15 -> 0.70020787 | J15: =MIN(G15,B15) -> 42779.9 | K15: =MAX(G15-B15,0) -> 0
A16: Dec 2023 | B16: ='Combined TOU Profile'!F7 -> 53252 | C16: 44140 | D16: =C16/'Model Assumptions'!$C$6 -> 91.010309 | E16: =ROUNDUP('Model Assumptions'!$C$4/('Model Assumptions'!$C$7/'Model Assumptions'!$C$8),0) -> 838 | F16: =E16*'Model Assumptions'!$C$5 -> 406.43 | G16: =C16*F16/'Model Assumptions'!$C$6 -> 36989.32 | H16: =G16-B16 -> -16262.68 | I16: =G16/B16 -> 0.69460903 | J16: =MIN(G16,B16) -> 36989.32 | K16: =MAX(G16-B16,0) -> 0
A17: Annual | B17: =SUM(B5:B16) -> 709501 | C17: =SUM(C5:C16) -> 847503 | D17: =C17/'Model Assumptions'!$C$6 -> 1747.4289 | E17: =E5 -> 838 | F17: =F5 -> 406.43 | G17: =SUM(G5:G16) -> 710207.51 | H17: =SUM(H5:H16) -> 706.514 | I17: =G17/B17 -> 1.0009958 | J17: =SUM(J5:J16) -> 615927.45 | K17: =SUM(K5:K16) -> 94280.068

Sheet ESS Sizing
A1: SPT6800 ESS Sizing — TOU Energy + Peak Demand
A2: Energy sizing uses average daily On+Mid-Peak energy; power sizing uses the fixed 100-kW proposal demand-shave target. The 215.04-kWh / 0.5C sizing basis comes from the SPT product material.
A4: Period | B4: Days | C4: On-Peak kWh | D4: Mid-Peak kWh | E4: Peak-Window Energy (kWh) | F4: Avg Daily Peak-Window Energy (kWh/day) | G4: Site Max-Demand Indicator (kW) | H4: Target Peak Shave (kW) | I4: Usable Delivered Energy / Unit (kWh) | J4: Power / Unit (kW) | K4: Units by Energy | L4: Units by Power | M4: Required Units | N4: Data Status
A5: ='Combined TOU Profile'!A5 -> Oct 2023 | B5: 29 | C5: ='Combined TOU Profile'!G5 -> 444 | D5: ='Combined TOU Profile'!H5 -> 1257 | E5: =SUM(C5:D5) -> 1701 | F5: =E5/B5 -> 58.655172 | G5: ='Combined TOU Profile'!M5 -> 552 | H5: ='Model Assumptions'!$C$30 -> 100 | I5: ='Model Assumptions'!$C$10*'Model Assumptions'!$C$13*'Model Assumptions'!$C$14 -> 183.8592 | J5: ='Model Assumptions'!$C$12 -> 107.52 | K5: =ROUNDUP(F5/I5,0) -> 1 | L5: =ROUNDUP(H5/J5,0) -> 1 | M5: =MAX(K5,L5) -> 1 | N5: ='Combined TOU Profile'!U5 -> Complete
A6: ='Combined TOU Profile'!A6 -> Nov 2023 | B6: 32 | C6: ='Combined TOU Profile'!G6 -> 0 | D6: ='Combined TOU Profile'!H6 -> 1654 | E6: =SUM(C6:D6) -> 1654 | F6: =E6/B6 -> 51.6875 | G6: ='Combined TOU Profile'!M6 -> 622 | H6: ='Model Assumptions'!$C$30 -> 100 | I6: ='Model Assumptions'!$C$10*'Model Assumptions'!$C$13*'Model Assumptions'!$C$14 -> 183.8592 | J6: ='Model Assumptions'!$C$12 -> 107.52 | K6: =ROUNDUP(F6/I6,0) -> 1 | L6: =ROUNDUP(H6/J6,0) -> 1 | M6: =MAX(K6,L6) -> 1 | N6: ='Combined TOU Profile'!U6 -> Complete
A7: ='Combined TOU Profile'!A7 -> Dec 2023 | B7: 30 | C7: ='Combined TOU Profile'!G7 -> 0 | D7: ='Combined TOU Profile'!H7 -> 2024 | E7: =SUM(C7:D7) -> 2024 | F7: =E7/B7 -> 67.466667 | G7: ='Combined TOU Profile'!M7 -> 513 | H7: ='Model Assumptions'!$C$30 -> 100 | I7: ='Model Assumptions'!$C$10*'Model Assumptions'!$C$13*'Model Assumptions'!$C$14 -> 183.8592 | J7: ='Model Assumptions'!$C$12 -> 107.52 | K7: =ROUNDUP(F7/I7,0) -> 1 | L7: =ROUNDUP(H7/J7,0) -> 1 | M7: =MAX(K7,L7) -> 1 | N7: ='Combined TOU Profile'!U7 -> Complete
A8: ='Combined TOU Profile'!A8 -> Jan 2024 | B8: 33 | C8: ='Combined TOU Profile'!G8 -> 0 | D8: ='Combined TOU Profile'!H8 -> 2137 | E8: =SUM(C8:D8) -> 2137 | F8: =E8/B8 -> 64.757576 | G8: ='Combined TOU Profile'!M8 -> 655 | H8: ='Model Assumptions'!$C$30 -> 100 | I8: ='Model Assumptions'!$C$10*'Model Assumptions'!$C$13*'Model Assumptions'!$C$14 -> 183.8592 | J8: ='Model Assumptions'!$C$12 -> 107.52 | K8: =ROUNDUP(F8/I8,0) -> 1 | L8: =ROUNDUP(H8/J8,0) -> 1 | M8: =MAX(K8,L8) -> 1 | N8: ='Combined TOU Profile'!U8 -> Complete
A9: ='Combined TOU Profile'!A9 -> Feb 2024 | B9: 30 | C9: ='Combined TOU Profile'!G9 -> 0 | D9: ='Combined TOU Profile'!H9 -> 1802 | E9: =SUM(C9:D9) -> 1802 | F9: =E9/B9 -> 60.066667 | G9: ='Combined TOU Profile'!M9 -> 640 | H9: ='Model Assumptions'!$C$30 -> 100 | I9: ='Model Assumptions'!$C$10*'Model Assumptions'!$C$13*'Model Assumptions'!$C$14 -> 183.8592 | J9: ='Model Assumptions'!$C$12 -> 107.52 | K9: =ROUNDUP(F9/I9,0) -> 1 | L9: =ROUNDUP(H9/J9,0) -> 1 | M9: =MAX(K9,L9) -> 1 | N9: ='Combined TOU Profile'!U9 -> Complete
A10: ='Combined TOU Profile'!A10 -> Mar 2024 | B10: 29 | C10: ='Combined TOU Profile'!G10 -> 0 | D10: ='Combined TOU Profile'!H10 -> 1437 | E10: =SUM(C10:D10) -> 1437 | F10: =E10/B10 -> 49.551724 | G10: ='Combined TOU Profile'!M10 -> 500 | H10: ='Model Assumptions'!$C$30 -> 100 | I10: ='Model Assumptions'!$C$10*'Model Assumptions'!$C$13*'Model Assumptions'!$C$14 -> 183.8592 | J10: ='Model Assumptions'!$C$12 -> 107.52 | K10: =ROUNDUP(F10/I10,0) -> 1 | L10: =ROUNDUP(H10/J10,0) -> 1 | M10: =MAX(K10,L10) -> 1 | N10: ='Combined TOU Profile'!U10 -> Complete
A11: ='Combined TOU Profile'!A11 -> Apr 2024 | B11: 32 | C11: ='Combined TOU Profile'!G11 -> 0 | D11: ='Combined TOU Profile'!H11 -> 1317 | E11: =SUM(C11:D11) -> 1317 | F11: =E11/B11 -> 41.15625 | G11: ='Combined TOU Profile'!M11 -> 442 | H11: ='Model Assumptions'!$C$30 -> 100 | I11: ='Model Assumptions'!$C$10*'Model Assumptions'!$C$13*'Model Assumptions'!$C$14 -> 183.8592 | J11: ='Model Assumptions'!$C$12 -> 107.52 | K11: =ROUNDUP(F11/I11,0) -> 1 | L11: =ROUNDUP(H11/J11,0) -> 1 | M11: =MAX(K11,L11) -> 1 | N11: ='Combined TOU Profile'!U11 -> Complete
A12: ='Combined TOU Profile'!A12 -> May 2024 | B12: 29 | C12: ='Combined TOU Profile'!G12 -> 403.83324 | D12: ='Combined TOU Profile'!H12 -> 876.32908 | E12: =SUM(C12:D12) -> 1280.1623 | F12: =E12/B12 -> 44.143528 | G12: ='Combined TOU Profile'!M12 -> 466 | H12: ='Model Assumptions'!$C$30 -> 100 | I12: ='Model Assumptions'!$C$10*'Model Assumptions'!$C$13*'Model Assumptions'!$C$14 -> 183.8592 | J12: ='Model Assumptions'!$C$12 -> 107.52 | K12: =ROUNDUP(F12/I12,0) -> 1 | L12: =ROUNDUP(H12/J12,0) -> 1 | M12: =MAX(K12,L12) -> 1 | N12: ='Combined TOU Profile'!U12 -> Estimated — Meter1 May TOU from adjacent periods
A13: ='Combined TOU Profile'!A13 -> Jun 2024 | B13: 30 | C13: ='Combined TOU Profile'!G13 -> 1008 | D13: ='Combined TOU Profile'!H13 -> 993 | E13: =SUM(C13:D13) -> 2001 | F13: =E13/B13 -> 66.7 | G13: ='Combined TOU Profile'!M13 -> 471 | H13: ='Model Assumptions'!$C$30 -> 100 | I13: ='Model Assumptions'!$C$10*'Model Assumptions'!$C$13*'Model Assumptions'!$C$14 -> 183.8592 | J13: ='Model Assumptions'!$C$12 -> 107.52 | K13: =ROUNDUP(F13/I13,0) -> 1 | L13: =ROUNDUP(H13/J13,0) -> 1 | M13: =MAX(K13,L13) -> 1 | N13: ='Combined TOU Profile'!U13 -> Complete
A14: ='Combined TOU Profile'!A14 -> Jul 2024 | B14: 33 | C14: ='Combined TOU Profile'!G14 -> 2075 | D14: ='Combined TOU Profile'!H14 -> 723 | E14: =SUM(C14:D14) -> 2798 | F14: =E14/B14 -> 84.787879 | G14: ='Combined TOU Profile'!M14 -> 725 | H14: ='Model Assumptions'!$C$30 -> 100 | I14: ='Model Assumptions'!$C$10*'Model Assumptions'!$C$13*'Model Assumptions'!$C$14 -> 183.8592 | J14: ='Model Assumptions'!$C$12 -> 107.52 | K14: =ROUNDUP(F14/I14,0) -> 1 | L14: =ROUNDUP(H14/J14,0) -> 1 | M14: =MAX(K14,L14) -> 1 | N14: ='Combined TOU Profile'!U14 -> Complete
A15: ='Combined TOU Profile'!A15 -> Aug 2024 | B15: 29 | C15: ='Combined TOU Profile'!G15 -> 4892 | D15: ='Combined TOU Profile'!H15 -> 631 | E15: =SUM(C15:D15) -> 5523 | F15: =E15/B15 -> 190.44828 | G15: ='Combined TOU Profile'!M15 -> 705 | H15: ='Model Assumptions'!$C$30 -> 100 | I15: ='Model Assumptions'!$C$10*'Model Assumptions'!$C$13*'Model Assumptions'!$C$14 -> 183.8592 | J15: ='Model Assumptions'!$C$12 -> 107.52 | K15: =ROUNDUP(F15/I15,0) -> 2 | L15: =ROUNDUP(H15/J15,0) -> 1 | M15: =MAX(K15,L15) -> 2 | N15: ='Combined TOU Profile'!U15 -> Complete
A16: ='Combined TOU Profile'!A16 -> Sep 2024 | B16: 30 | C16: ='Combined TOU Profile'!G16 -> 3782 | D16: ='Combined TOU Profile'!H16 -> 629 | E16: =SUM(C16:D16) -> 4411 | F16: =E16/B16 -> 147.03333 | G16: ='Combined TOU Profile'!M16 -> 730 | H16: ='Model Assumptions'!$C$30 -> 100 | I16: ='Model Assumptions'!$C$10*'Model Assumptions'!$C$13*'Model Assumptions'!$C$14 -> 183.8592 | J16: ='Model Assumptions'!$C$12 -> 107.52 | K16: =ROUNDUP(F16/I16,0) -> 1 | L16: =ROUNDUP(H16/J16,0) -> 1 | M16: =MAX(K16,L16) -> 1 | N16: ='Combined TOU Profile'!U16 -> Complete
A17: Design Requirement | F17: =MAX(F5:F16) -> 190.44828 | G17: =MAX(G5:G16) -> 730 | H17: =MAX(H5:H16) -> 100 | I17: =I5 -> 183.8592 | J17: =J5 -> 107.52 | K17: =MAX(K5:K16) -> 2 | L17: =MAX(L5:L16) -> 1 | M17: =MAX(M5:M16) -> 2

Sheet Scenarios
A1: PV + ESS Configuration Scenarios
A3: Scenario | B3: PV Panels | C3: PV DC (kW) | D3: Annual PV Gen (kWh) | E3: Annual Coverage | F3: ESS Units | G3: ESS Nominal Energy (kWh) | H3: ESS Screening Power (kW) | I3: Energy Sizing Pass | J3: Power Sizing Pass | K3: PV Cost ($) | L3: ESS Cost ($) | M3: Total Installed Cost ($) | N3: Year-1 Screening Savings ($) | O3: Simple Payback (yrs) | P3: Constraint Status
A4: Minimum | B4: 838 | C4: =B4*'Model Assumptions'!$C$5 -> 406.43 | D4: ='Model Assumptions'!$C$7*C4/'Model Assumptions'!$C$6 -> 710207.51 | E4: =D4/'Model Assumptions'!$C$4 -> 1.0009958 | F4: 2 | G4: =F4*'Model Assumptions'!$C$10 -> 430.08 | H4: =F4*'Model Assumptions'!$C$12 -> 215.04 | I4: =IF(F4>='ESS Sizing'!$M$17,"PASS","FAIL") -> PASS | J4: =IF(H4>='ESS Sizing'!$H$17,"PASS","FAIL") -> PASS | K4: =C4*1000*'Model Assumptions'!$C$17 -> 816924.3 | L4: =G4*'Model Assumptions'!$C$18 -> 258048 | M4: =K4+L4 -> 1074972.3 | N4: =Financial!L5 -> 100318.07 | O4: =M4/N4 -> 10.71564 | P4: =IF(AND(E4>='Model Assumptions'!$C$9,I4="PASS",J4="PASS"),"PASS","FAIL") -> PASS
A5: Balanced A | B5: 850 | C5: =B5*'Model Assumptions'!$C$5 -> 412.25 | D5: ='Model Assumptions'!$C$7*C5/'Model Assumptions'!$C$6 -> 720377.55 | E5: =D5/'Model Assumptions'!$C$4 -> 1.0153299 | F5: 2 | G5: =F5*'Model Assumptions'!$C$10 -> 430.08 | H5: =F5*'Model Assumptions'!$C$12 -> 215.04 | I5: =IF(F5>='ESS Sizing'!$M$17,"PASS","FAIL") -> PASS | J5: =IF(H5>='ESS Sizing'!$H$17,"PASS","FAIL") -> PASS | K5: =C5*1000*'Model Assumptions'!$C$17 -> 828622.5 | L5: =G5*'Model Assumptions'!$C$18 -> 258048 | M5: =K5+L5 -> 1086670.5 | N5: =Financial!L6 -> 101051.39 | O5: =M5/N5 -> 10.753643 | P5: =IF(AND(E5>='Model Assumptions'!$C$9,I5="PASS",J5="PASS"),"PASS","FAIL") -> PASS
A6: Balanced B | B6: 875 | C6: =B6*'Model Assumptions'!$C$5 -> 424.375 | D6: ='Model Assumptions'!$C$7*C6/'Model Assumptions'!$C$6 -> 741565.12 | E6: =D6/'Model Assumptions'!$C$4 -> 1.0451925 | F6: 3 | G6: =F6*'Model Assumptions'!$C$10 -> 645.12 | H6: =F6*'Model Assumptions'!$C$12 -> 322.56 | I6: =IF(F6>='ESS Sizing'!$M$17,"PASS","FAIL") -> PASS | J6: =IF(H6>='ESS Sizing'!$H$17,"PASS","FAIL") -> PASS | K6: =C6*1000*'Model Assumptions'!$C$17 -> 852993.75 | L6: =G6*'Model Assumptions'!$C$18 -> 387072 | M6: =K6+L6 -> 1240065.8 | N6: =Financial!L7 -> 102579.13 | O6: =M6/N6 -> 12.088869 | P6: =IF(AND(E6>='Model Assumptions'!$C$9,I6="PASS",J6="PASS"),"PASS","FAIL") -> PASS
A7: Higher Storage | B7: 900 | C7: =B7*'Model Assumptions'!$C$5 -> 436.5 | D7: ='Model Assumptions'!$C$7*C7/'Model Assumptions'!$C$6 -> 762752.7 | E7: =D7/'Model Assumptions'!$C$4 -> 1.0750551 | F7: 4 | G7: =F7*'Model Assumptions'!$C$10 -> 860.16 | H7: =F7*'Model Assumptions'!$C$12 -> 430.08 | I7: =IF(F7>='ESS Sizing'!$M$17,"PASS","FAIL") -> PASS | J7: =IF(H7>='ESS Sizing'!$H$17,"PASS","FAIL") -> PASS | K7: =C7*1000*'Model Assumptions'!$C$17 -> 877365 | L7: =G7*'Model Assumptions'!$C$18 -> 516096 | M7: =K7+L7 -> 1393461 | N7: =Financial!L8 -> 104048.73 | O7: =M7/N7 -> 13.392388 | P7: =IF(AND(E7>='Model Assumptions'!$C$9,I7="PASS",J7="PASS"),"PASS","FAIL") -> PASS
A8: Historical PV Scale | B8: 1000 | C8: =B8*'Model Assumptions'!$C$5 -> 485 | D8: ='Model Assumptions'!$C$7*C8/'Model Assumptions'!$C$6 -> 847503 | E8: =D8/'Model Assumptions'!$C$4 -> 1.1945057 | F8: 6 | G8: =F8*'Model Assumptions'!$C$10 -> 1290.24 | H8: =F8*'Model Assumptions'!$C$12 -> 645.12 | I8: =IF(F8>='ESS Sizing'!$M$17,"PASS","FAIL") -> PASS | J8: =IF(H8>='ESS Sizing'!$H$17,"PASS","FAIL") -> PASS | K8: =C8*1000*'Model Assumptions'!$C$17 -> 974850 | L8: =G8*'Model Assumptions'!$C$18 -> 774144 | M8: =K8+L8 -> 1748994 | N8: =Financial!L9 -> 109696.21 | O8: =M8/N8 -> 15.943979 | P8: =IF(AND(E8>='Model Assumptions'!$C$9,I8="PASS",J8="PASS"),"PASS","FAIL") -> PASS

Sheet Financial
A1: Preliminary Electricity-Cost Savings
A2: PV savings use extracted historical energy-charge intensity for self-consumed load plus an editable export value for surplus. ESS demand savings use the target peak-shave fraction applied to extracted historical demand charges.
A4: Scenario | B4: PV Panels | C4: ESS Units | D4: PV Gen (kWh) | E4: Self-Consumed PV Proxy (kWh) | F4: PV Surplus (kWh) | G4: Historical Energy-Charge Rate ($/kWh) | H4: PV Energy Savings ($) | I4: PV Export Value ($) | J4: ESS Demand Savings ($) | K4: Other ESS TOU Arbitrage ($) | L4: Year-1 Screening Savings ($)
A5: =Scenarios!A4 -> Minimum | B5: =Scenarios!B4 -> 838 | C5: =Scenarios!F4 -> 2 | D5: =Scenarios!D4 -> 710207.51 | E5: =MIN('Combined TOU Profile'!F8,51780*(Scenarios!C4/'Model Assumptions'!$C$6))+MIN('Combined TOU Profile'!F9,55888*(Scenarios!C4/'Model Assumptions'!$C$6))+MIN('Combined TOU Profile'!F10,73686*(Scenarios!C4/'Model Assumptions'!$C$6))+MIN('Combined TOU Profile'!F11,82939*(Scenarios!C4/'Model Assumptions'!$C$6))+MIN('Combined TOU Profile'!F12,91798*(Scenarios!C4/'Model Assumptions'!$C$6))+MIN('Combined TOU Profile'!F13,91057*(Scenarios!C4/'Model Assumptions'!$C$6))+MIN('Combined TOU Profile'!F14,84094*(Scenarios!C4/'Model Assumptions'!$C$6))+MIN('Combined TOU Profile'!F15,83095*(Scenarios!C4/'Model Assumptions'!$C$6))+MIN('Combined TOU Profile'!F16,72370*(Scenarios!C4/'Model Assumptions'!$C$6))+MIN('Combined TOU Profile'!F5,65606*(Scenarios!C4/'Model Assumptions'!$C$6))+MIN('Combined TOU Profile'!F6,51050*(Scenarios!C4/'Model Assumptions'!$C$6))+MIN('Combined TOU Profile'!F7,44140*(Scenarios!C4/'Model Assumptions'!$C$6)) -> 615927.45 | F5: =MAX(D5-E5,0) -> 94280.068 | G5: ='Combined TOU Profile'!P17/'Combined TOU Profile'!F17 -> 0.092346318 | H5: =E5*G5 -> 56878.632 | I5: =F5*'Model Assumptions'!$C$16 -> 4714.0034 | J5: ='Combined TOU Profile'!Q17*MIN('Model Assumptions'!$C$15,(Scenarios!H4/'ESS Sizing'!$G$17)) -> 38725.434 | K5: 0 | L5: =SUM(H5:K5) -> 100318.07
A6: =Scenarios!A5 -> Balanced A | B6: =Scenarios!B5 -> 850 | C6: =Scenarios!F5 -> 2 | D6: =Scenarios!D5 -> 720377.55 | E6: =MIN('Combined TOU Profile'!F8,51780*(Scenarios!C5/'Model Assumptions'!$C$6))+MIN('Combined TOU Profile'!F9,55888*(Scenarios!C5/'Model Assumptions'!$C$6))+MIN('Combined TOU Profile'!F10,73686*(Scenarios!C5/'Model Assumptions'!$C$6))+MIN('Combined TOU Profile'!F11,82939*(Scenarios!C5/'Model Assumptions'!$C$6))+MIN('Combined TOU Profile'!F12,91798*(Scenarios!C5/'Model Assumptions'!$C$6))+MIN('Combined TOU Profile'!F13,91057*(Scenarios!C5/'Model Assumptions'!$C$6))+MIN('Combined TOU Profile'!F14,84094*(Scenarios!C5/'Model Assumptions'!$C$6))+MIN('Combined TOU Profile'!F15,83095*(Scenarios!C5/'Model Assumptions'!$C$6))+MIN('Combined TOU Profile'!F16,72370*(Scenarios!C5/'Model Assumptions'!$C$6))+MIN('Combined TOU Profile'!F5,65606*(Scenarios!C5/'Model Assumptions'!$C$6))+MIN('Combined TOU Profile'!F6,51050*(Scenarios!C5/'Model Assumptions'!$C$6))+MIN('Combined TOU Profile'!F7,44140*(Scenarios!C5/'Model Assumptions'!$C$6)) -> 621236.45 | F6: =MAX(D6-E6,0) -> 99141.1 | G6: ='Combined TOU Profile'!P17/'Combined TOU Profile'!F17 -> 0.092346318 | H6: =E6*G6 -> 57368.898 | I6: =F6*'Model Assumptions'!$C$16 -> 4957.055 | J6: ='Combined TOU Profile'!Q17*MIN('Model Assumptions'!$C$15,(Scenarios!H5/'ESS Sizing'!$G$17)) -> 38725.434 | K6: 0 | L6: =SUM(H6:K6) -> 101051.39
A7: =Scenarios!A6 -> Balanced B | B7: =Scenarios!B6 -> 875 | C7: =Scenarios!F6 -> 3 | D7: =Scenarios!D6 -> 741565.12 | E7: =MIN('Combined TOU Profile'!F8,51780*(Scenarios!C6/'Model Assumptions'!$C$6))+MIN('Combined TOU Profile'!F9,55888*(Scenarios!C6/'Model Assumptions'!$C$6))+MIN('Combined TOU Profile'!F10,73686*(Scenarios!C6/'Model Assumptions'!$C$6))+MIN('Combined TOU Profile'!F11,82939*(Scenarios!C6/'Model Assumptions'!$C$6))+MIN('Combined TOU Profile'!F12,91798*(Scenarios!C6/'Model Assumptions'!$C$6))+MIN('Combined TOU Profile'!F13,91057*(Scenarios!C6/'Model Assumptions'!$C$6))+MIN('Combined TOU Profile'!F14,84094*(Scenarios!C6/'Model Assumptions'!$C$6))+MIN('Combined TOU Profile'!F15,83095*(Scenarios!C6/'Model Assumptions'!$C$6))+MIN('Combined TOU Profile'!F16,72370*(Scenarios!C6/'Model Assumptions'!$C$6))+MIN('Combined TOU Profile'!F5,65606*(Scenarios!C6/'Model Assumptions'!$C$6))+MIN('Combined TOU Profile'!F6,51050*(Scenarios!C6/'Model Assumptions'!$C$6))+MIN('Combined TOU Profile'!F7,44140*(Scenarios!C6/'Model Assumptions'!$C$6)) -> 632296.88 | F7: =MAX(D7-E7,0) -> 109268.25 | G7: ='Combined TOU Profile'!P17/'Combined TOU Profile'!F17 -> 0.092346318 | H7: =E7*G7 -> 58390.288 | I7: =F7*'Model Assumptions'!$C$16 -> 5463.4125 | J7: ='Combined TOU Profile'!Q17*MIN('Model Assumptions'!$C$15,(Scenarios!H6/'ESS Sizing'!$G$17)) -> 38725.434 | K7: 0 | L7: =SUM(H7:K7) -> 102579.13
A8: =Scenarios!A7 -> Higher Storage | B8: =Scenarios!B7 -> 900 | C8: =Scenarios!F7 -> 4 | D8: =Scenarios!D7 -> 762752.7 | E8: =MIN('Combined TOU Profile'!F8,51780*(Scenarios!C7/'Model Assumptions'!$C$6))+MIN('Combined TOU Profile'!F9,55888*(Scenarios!C7/'Model Assumptions'!$C$6))+MIN('Combined TOU Profile'!F10,73686*(Scenarios!C7/'Model Assumptions'!$C$6))+MIN('Combined TOU Profile'!F11,82939*(Scenarios!C7/'Model Assumptions'!$C$6))+MIN('Combined TOU Profile'!F12,91798*(Scenarios!C7/'Model Assumptions'!$C$6))+MIN('Combined TOU Profile'!F13,91057*(Scenarios!C7/'Model Assumptions'!$C$6))+MIN('Combined TOU Profile'!F14,84094*(Scenarios!C7/'Model Assumptions'!$C$6))+MIN('Combined TOU Profile'!F15,83095*(Scenarios!C7/'Model Assumptions'!$C$6))+MIN('Combined TOU Profile'!F16,72370*(Scenarios!C7/'Model Assumptions'!$C$6))+MIN('Combined TOU Profile'!F5,65606*(Scenarios!C7/'Model Assumptions'!$C$6))+MIN('Combined TOU Profile'!F6,51050*(Scenarios!C7/'Model Assumptions'!$C$6))+MIN('Combined TOU Profile'!F7,44140*(Scenarios!C7/'Model Assumptions'!$C$6)) -> 641984.1 | F8: =MAX(D8-E8,0) -> 120768.6 | G8: ='Combined TOU Profile'!P17/'Combined TOU Profile'!F17 -> 0.092346318 | H8: =E8*G8 -> 59284.868 | I8: =F8*'Model Assumptions'!$C$16 -> 6038.43 | J8: ='Combined TOU Profile'!Q17*MIN('Model Assumptions'!$C$15,(Scenarios!H7/'ESS Sizing'!$G$17)) -> 38725.434 | K8: 0 | L8: =SUM(H8:K8) -> 104048.73
A9: =Scenarios!A8 -> Historical PV Scale | B9: =Scenarios!B8 -> 1000 | C9: =Scenarios!F8 -> 6 | D9: =Scenarios!D8 -> 847503 | E9: =MIN('Combined TOU Profile'!F8,51780*(Scenarios!C8/'Model Assumptions'!$C$6))+MIN('Combined TOU Profile'!F9,55888*(Scenarios!C8/'Model Assumptions'!$C$6))+MIN('Combined TOU Profile'!F10,73686*(Scenarios!C8/'Model Assumptions'!$C$6))+MIN('Combined TOU Profile'!F11,82939*(Scenarios!C8/'Model Assumptions'!$C$6))+MIN('Combined TOU Profile'!F12,91798*(Scenarios!C8/'Model Assumptions'!$C$6))+MIN('Combined TOU Profile'!F13,91057*(Scenarios!C8/'Model Assumptions'!$C$6))+MIN('Combined TOU Profile'!F14,84094*(Scenarios!C8/'Model Assumptions'!$C$6))+MIN('Combined TOU Profile'!F15,83095*(Scenarios!C8/'Model Assumptions'!$C$6))+MIN('Combined TOU Profile'!F16,72370*(Scenarios!C8/'Model Assumptions'!$C$6))+MIN('Combined TOU Profile'!F5,65606*(Scenarios!C8/'Model Assumptions'!$C$6))+MIN('Combined TOU Profile'!F6,51050*(Scenarios!C8/'Model Assumptions'!$C$6))+MIN('Combined TOU Profile'!F7,44140*(Scenarios!C8/'Model Assumptions'!$C$6)) -> 675280 | F9: =MAX(D9-E9,0) -> 172223 | G9: ='Combined TOU Profile'!P17/'Combined TOU Profile'!F17 -> 0.092346318 | H9: =E9*G9 -> 62359.621 | I9: =F9*'Model Assumptions'!$C$16 -> 8611.15 | J9: ='Combined TOU Profile'!Q17*MIN('Model Assumptions'!$C$15,(Scenarios!H8/'ESS Sizing'!$G$17)) -> 38725.434 | K9: 0 | L9: =SUM(H9:K9) -> 109696.21
A12: Metric | B12: Value
A13: Historical 12-period bill total | B13: ='Combined TOU Profile'!R17 -> 286732.11
A14: Extracted energy charges | B14: ='Combined TOU Profile'!P17 -> 65519.805
A15: Extracted demand charges | B15: ='Combined TOU Profile'!Q17 -> 193627.17
A16: Residual / other charges | B16: ='Combined TOU Profile'!S17 -> 27585.135
A17: Blended extracted energy-charge rate | B17: =B14/'Combined TOU Profile'!F17 -> 0.092346318

Sheet Recommendation
A1: Recommended Configuration
A3: Metric | B3: Recommended / Result
A4: Recommended scenario | B4: =INDEX(Scenarios!A4:A8,MATCH("PASS",Scenarios!P4:P8,0)) -> Minimum
A5: PV panels | B5: =INDEX(Scenarios!B4:B8,MATCH("PASS",Scenarios!P4:P8,0)) -> 838
A6: PV DC capacity (kW) | B6: =INDEX(Scenarios!C4:C8,MATCH("PASS",Scenarios!P4:P8,0)) -> 406.43
A7: Annual modeled PV generation (kWh) | B7: =INDEX(Scenarios!D4:D8,MATCH("PASS",Scenarios!P4:P8,0)) -> 710207.51
A8: Annual generation coverage | B8: =INDEX(Scenarios!E4:E8,MATCH("PASS",Scenarios!P4:P8,0)) -> 1.0009958
A9: SPT ~215-kWh sizing units | B9: =INDEX(Scenarios!F4:F8,MATCH("PASS",Scenarios!P4:P8,0)) -> 2
A10: Nominal ESS energy (kWh) | B10: =INDEX(Scenarios!G4:G8,MATCH("PASS",Scenarios!P4:P8,0)) -> 430.08
A11: ESS power (kW) | B11: =INDEX(Scenarios!H4:H8,MATCH("PASS",Scenarios!P4:P8,0)) -> 215.04
A13: Interpretation / limitations
A14: The recommendation is the lowest-cost scenario that satisfies two constraints: (1) annual PV generation >= 709,501 kWh; (2) ESS units meet the average-daily On+Mid-Peak energy requirement.

Sheet Sources
A1: Model Sources & Evidence Register
A3: Source | B3: Used For | C3: Status | D3: Key Values | E3: Citation / File
A4: Barstow Historical Load & TOU Profile | B4: Load, TOU, demand, historical bill charges | C4: Verified + one labeled estimate | D4: 709,501 kWh annual baseline; Meter 1 May TOU estimated | E4: Barstow_Historical_Load_TOU_Profile_Completed.xlsx
A5: SPT product introduction | B5: ESS sizing-unit basis | C5: Product source | D5: 215.04 kWh battery cluster; 0.5C design discharge rate | E5: Internal Dataset
A6: Model assumptions | B6: Tech specifications, policy parameters, calculation metrics | C6: Editable assumptions | D6: Analysis horizon, Discount rate, Electricity escalation, PV degradation | E6: Model Assumptions sheet
